2024-11-20 21:05:38,096 - INFO - [31m[1mWARNING: This is a development server. Do not use it in a production deployment. Use a production WSGI server instead.[0m
 * Running on http://127.0.0.1:5000
2024-11-20 21:05:38,096 - INFO - [33mPress CTRL+C to quit[0m
2024-11-20 21:06:20,806 - INFO - 127.0.0.1 - - [20/Nov/2024 21:06:20] "GET / HTTP/1.1" 200 -
2024-11-20 21:06:20,865 - ERROR - Error occurred: 404 Not Found: The requested URL was not found on the server. If you entered the URL manually please check your spelling and try again.
Traceback (most recent call last):
  File "C:\Users\andre\AppData\Local\Packages\PythonSoftwareFoundation.Python.3.11_qbz5n2kfra8p0\LocalCache\local-packages\Python311\site-packages\flask\app.py", line 917, in full_dispatch_request
    rv = self.dispatch_request()
         ^^^^^^^^^^^^^^^^^^^^^^^
  File "C:\Users\andre\AppData\Local\Packages\PythonSoftwareFoundation.Python.3.11_qbz5n2kfra8p0\LocalCache\local-packages\Python311\site-packages\flask\app.py", line 902, in dispatch_request
    return self.ensure_sync(self.view_functions[rule.endpoint])(**view_args)  # type: ignore[no-any-return]
           ^^^^^^^^^^^^^^^^^^^^^^^^^^^^^^^^^^^^^^^^^^^^^^^^^^^^^^^^^^^^^^^^^
  File "C:\Users\andre\AppData\Local\Packages\PythonSoftwareFoundation.Python.3.11_qbz5n2kfra8p0\LocalCache\local-packages\Python311\site-packages\flask\app.py", line 278, in <lambda>
    view_func=lambda **kw: self_ref().send_static_file(**kw),  # type: ignore # noqa: B950
                           ^^^^^^^^^^^^^^^^^^^^^^^^^^^^^^^^^
  File "C:\Users\andre\AppData\Local\Packages\PythonSoftwareFoundation.Python.3.11_qbz5n2kfra8p0\LocalCache\local-packages\Python311\site-packages\flask\app.py", line 326, in send_static_file
    return send_from_directory(
           ^^^^^^^^^^^^^^^^^^^^
  File "C:\Users\andre\AppData\Local\Packages\PythonSoftwareFoundation.Python.3.11_qbz5n2kfra8p0\LocalCache\local-packages\Python311\site-packages\flask\helpers.py", line 565, in send_from_directory
    return werkzeug.utils.send_from_directory(  # type: ignore[return-value]
           ^^^^^^^^^^^^^^^^^^^^^^^^^^^^^^^^^^^^^^^^^^^^^^^^^^^^^^^^^^^^^^^^^
  File "C:\Users\andre\AppData\Local\Packages\PythonSoftwareFoundation.Python.3.11_qbz5n2kfra8p0\LocalCache\local-packages\Python311\site-packages\werkzeug\utils.py", line 575, in send_from_directory
    raise NotFound()
werkzeug.exceptions.NotFound: 404 Not Found: The requested URL was not found on the server. If you entered the URL manually please check your spelling and try again.
2024-11-20 21:06:20,922 - INFO - 127.0.0.1 - - [20/Nov/2024 21:06:20] "[35m[1mGET /favicon.ico HTTP/1.1[0m" 500 -
2024-11-20 21:06:33,012 - INFO - Chat request received - length: 2
2024-11-20 21:06:33,012 - ERROR - Error occurred: module 'openai' has no attribute 'error'
Traceback (most recent call last):
  File "c:\Users\andre\CascadeProjects\windsurf-project\ccwithai-chatbot\app.py", line 65, in chat
    response = openai.ChatCompletion.create(
               ^^^^^^^^^^^^^^^^^^^^^^^^^^^^
  File "C:\Users\andre\AppData\Local\Packages\PythonSoftwareFoundation.Python.3.11_qbz5n2kfra8p0\LocalCache\local-packages\Python311\site-packages\openai\_utils\_proxy.py", line 22, in __getattr__
    return getattr(self.__get_proxied__(), attr)
                   ^^^^^^^^^^^^^^^^^^^^^^
  File "C:\Users\andre\AppData\Local\Packages\PythonSoftwareFoundation.Python.3.11_qbz5n2kfra8p0\LocalCache\local-packages\Python311\site-packages\openai\_utils\_proxy.py", line 43, in __get_proxied__
    return self.__load__()
           ^^^^^^^^^^^^^^^
  File "C:\Users\andre\AppData\Local\Packages\PythonSoftwareFoundation.Python.3.11_qbz5n2kfra8p0\LocalCache\local-packages\Python311\site-packages\openai\lib\_old_api.py", line 33, in __load__
    raise APIRemovedInV1(symbol=self._symbol)
openai.lib._old_api.APIRemovedInV1: 

You tried to access openai.ChatCompletion, but this is no longer supported in openai>=1.0.0 - see the README at https://github.com/openai/openai-python for the API.

You can run `openai migrate` to automatically upgrade your codebase to use the 1.0.0 interface. 

Alternatively, you can pin your installation to the old version, e.g. `pip install openai==0.28`

A detailed migration guide is available here: https://github.com/openai/openai-python/discussions/742


During handling of the above exception, another exception occurred:

Traceback (most recent call last):
  File "C:\Users\andre\AppData\Local\Packages\PythonSoftwareFoundation.Python.3.11_qbz5n2kfra8p0\LocalCache\local-packages\Python311\site-packages\flask\app.py", line 917, in full_dispatch_request
    rv = self.dispatch_request()
         ^^^^^^^^^^^^^^^^^^^^^^^
  File "C:\Users\andre\AppData\Local\Packages\PythonSoftwareFoundation.Python.3.11_qbz5n2kfra8p0\LocalCache\local-packages\Python311\site-packages\flask\app.py", line 902, in dispatch_request
    return self.ensure_sync(self.view_functions[rule.endpoint])(**view_args)  # type: ignore[no-any-return]
           ^^^^^^^^^^^^^^^^^^^^^^^^^^^^^^^^^^^^^^^^^^^^^^^^^^^^^^^^^^^^^^^^^
  File "c:\Users\andre\CascadeProjects\windsurf-project\ccwithai-chatbot\app.py", line 84, in chat
    except openai.error.OpenAIError as e:
           ^^^^^^^^^^^^
AttributeError: module 'openai' has no attribute 'error'
2024-11-20 21:06:33,047 - INFO - 127.0.0.1 - - [20/Nov/2024 21:06:33] "[35m[1mPOST /api/chat HTTP/1.1[0m" 500 -
2024-11-20 21:07:10,648 - ERROR - Error occurred: 404 Not Found: The requested URL was not found on the server. If you entered the URL manually please check your spelling and try again.
Traceback (most recent call last):
  File "C:\Users\andre\AppData\Local\Packages\PythonSoftwareFoundation.Python.3.11_qbz5n2kfra8p0\LocalCache\local-packages\Python311\site-packages\flask\app.py", line 917, in full_dispatch_request
    rv = self.dispatch_request()
         ^^^^^^^^^^^^^^^^^^^^^^^
  File "C:\Users\andre\AppData\Local\Packages\PythonSoftwareFoundation.Python.3.11_qbz5n2kfra8p0\LocalCache\local-packages\Python311\site-packages\flask\app.py", line 902, in dispatch_request
    return self.ensure_sync(self.view_functions[rule.endpoint])(**view_args)  # type: ignore[no-any-return]
           ^^^^^^^^^^^^^^^^^^^^^^^^^^^^^^^^^^^^^^^^^^^^^^^^^^^^^^^^^^^^^^^^^
  File "C:\Users\andre\AppData\Local\Packages\PythonSoftwareFoundation.Python.3.11_qbz5n2kfra8p0\LocalCache\local-packages\Python311\site-packages\flask\app.py", line 278, in <lambda>
    view_func=lambda **kw: self_ref().send_static_file(**kw),  # type: ignore # noqa: B950
                           ^^^^^^^^^^^^^^^^^^^^^^^^^^^^^^^^^
  File "C:\Users\andre\AppData\Local\Packages\PythonSoftwareFoundation.Python.3.11_qbz5n2kfra8p0\LocalCache\local-packages\Python311\site-packages\flask\app.py", line 326, in send_static_file
    return send_from_directory(
           ^^^^^^^^^^^^^^^^^^^^
  File "C:\Users\andre\AppData\Local\Packages\PythonSoftwareFoundation.Python.3.11_qbz5n2kfra8p0\LocalCache\local-packages\Python311\site-packages\flask\helpers.py", line 565, in send_from_directory
    return werkzeug.utils.send_from_directory(  # type: ignore[return-value]
           ^^^^^^^^^^^^^^^^^^^^^^^^^^^^^^^^^^^^^^^^^^^^^^^^^^^^^^^^^^^^^^^^^
  File "C:\Users\andre\AppData\Local\Packages\PythonSoftwareFoundation.Python.3.11_qbz5n2kfra8p0\LocalCache\local-packages\Python311\site-packages\werkzeug\utils.py", line 575, in send_from_directory
    raise NotFound()
werkzeug.exceptions.NotFound: 404 Not Found: The requested URL was not found on the server. If you entered the URL manually please check your spelling and try again.
2024-11-20 21:07:10,648 - INFO - 127.0.0.1 - - [20/Nov/2024 21:07:10] "[35m[1mGET /manage HTTP/1.1[0m" 500 -
2024-11-20 21:11:00,480 - INFO - [31m[1mWARNING: This is a development server. Do not use it in a production deployment. Use a production WSGI server instead.[0m
 * Running on http://127.0.0.1:5000
2024-11-20 21:11:00,480 - INFO - [33mPress CTRL+C to quit[0m
2024-11-20 21:11:26,735 - INFO - 127.0.0.1 - - [20/Nov/2024 21:11:26] "[36mGET / HTTP/1.1[0m" 304 -
2024-11-20 21:11:26,778 - ERROR - Error occurred: 404 Not Found: The requested URL was not found on the server. If you entered the URL manually please check your spelling and try again.
Traceback (most recent call last):
  File "C:\Users\andre\AppData\Local\Packages\PythonSoftwareFoundation.Python.3.11_qbz5n2kfra8p0\LocalCache\local-packages\Python311\site-packages\flask\app.py", line 917, in full_dispatch_request
    rv = self.dispatch_request()
         ^^^^^^^^^^^^^^^^^^^^^^^
  File "C:\Users\andre\AppData\Local\Packages\PythonSoftwareFoundation.Python.3.11_qbz5n2kfra8p0\LocalCache\local-packages\Python311\site-packages\flask\app.py", line 902, in dispatch_request
    return self.ensure_sync(self.view_functions[rule.endpoint])(**view_args)  # type: ignore[no-any-return]
           ^^^^^^^^^^^^^^^^^^^^^^^^^^^^^^^^^^^^^^^^^^^^^^^^^^^^^^^^^^^^^^^^^
  File "C:\Users\andre\AppData\Local\Packages\PythonSoftwareFoundation.Python.3.11_qbz5n2kfra8p0\LocalCache\local-packages\Python311\site-packages\flask\app.py", line 278, in <lambda>
    view_func=lambda **kw: self_ref().send_static_file(**kw),  # type: ignore # noqa: B950
                           ^^^^^^^^^^^^^^^^^^^^^^^^^^^^^^^^^
  File "C:\Users\andre\AppData\Local\Packages\PythonSoftwareFoundation.Python.3.11_qbz5n2kfra8p0\LocalCache\local-packages\Python311\site-packages\flask\app.py", line 326, in send_static_file
    return send_from_directory(
           ^^^^^^^^^^^^^^^^^^^^
  File "C:\Users\andre\AppData\Local\Packages\PythonSoftwareFoundation.Python.3.11_qbz5n2kfra8p0\LocalCache\local-packages\Python311\site-packages\flask\helpers.py", line 565, in send_from_directory
    return werkzeug.utils.send_from_directory(  # type: ignore[return-value]
           ^^^^^^^^^^^^^^^^^^^^^^^^^^^^^^^^^^^^^^^^^^^^^^^^^^^^^^^^^^^^^^^^^
  File "C:\Users\andre\AppData\Local\Packages\PythonSoftwareFoundation.Python.3.11_qbz5n2kfra8p0\LocalCache\local-packages\Python311\site-packages\werkzeug\utils.py", line 575, in send_from_directory
    raise NotFound()
werkzeug.exceptions.NotFound: 404 Not Found: The requested URL was not found on the server. If you entered the URL manually please check your spelling and try again.
2024-11-20 21:11:26,779 - INFO - 127.0.0.1 - - [20/Nov/2024 21:11:26] "[35m[1mGET /favicon.ico HTTP/1.1[0m" 500 -
2024-11-20 21:11:30,434 - INFO - Chat request received - length: 2
2024-11-20 21:11:30,435 - ERROR - Error occurred: module 'openai' has no attribute 'error'
Traceback (most recent call last):
  File "c:\Users\andre\CascadeProjects\windsurf-project\ccwithai-chatbot\app.py", line 65, in chat
    response = openai.ChatCompletion.create(
               ^^^^^^^^^^^^^^^^^^^^^^^^^^^^
  File "C:\Users\andre\AppData\Local\Packages\PythonSoftwareFoundation.Python.3.11_qbz5n2kfra8p0\LocalCache\local-packages\Python311\site-packages\openai\_utils\_proxy.py", line 22, in __getattr__
    return getattr(self.__get_proxied__(), attr)
                   ^^^^^^^^^^^^^^^^^^^^^^
  File "C:\Users\andre\AppData\Local\Packages\PythonSoftwareFoundation.Python.3.11_qbz5n2kfra8p0\LocalCache\local-packages\Python311\site-packages\openai\_utils\_proxy.py", line 43, in __get_proxied__
    return self.__load__()
           ^^^^^^^^^^^^^^^
  File "C:\Users\andre\AppData\Local\Packages\PythonSoftwareFoundation.Python.3.11_qbz5n2kfra8p0\LocalCache\local-packages\Python311\site-packages\openai\lib\_old_api.py", line 33, in __load__
    raise APIRemovedInV1(symbol=self._symbol)
openai.lib._old_api.APIRemovedInV1: 

You tried to access openai.ChatCompletion, but this is no longer supported in openai>=1.0.0 - see the README at https://github.com/openai/openai-python for the API.

You can run `openai migrate` to automatically upgrade your codebase to use the 1.0.0 interface. 

Alternatively, you can pin your installation to the old version, e.g. `pip install openai==0.28`

A detailed migration guide is available here: https://github.com/openai/openai-python/discussions/742


During handling of the above exception, another exception occurred:

Traceback (most recent call last):
  File "C:\Users\andre\AppData\Local\Packages\PythonSoftwareFoundation.Python.3.11_qbz5n2kfra8p0\LocalCache\local-packages\Python311\site-packages\flask\app.py", line 917, in full_dispatch_request
    rv = self.dispatch_request()
         ^^^^^^^^^^^^^^^^^^^^^^^
  File "C:\Users\andre\AppData\Local\Packages\PythonSoftwareFoundation.Python.3.11_qbz5n2kfra8p0\LocalCache\local-packages\Python311\site-packages\flask\app.py", line 902, in dispatch_request
    return self.ensure_sync(self.view_functions[rule.endpoint])(**view_args)  # type: ignore[no-any-return]
           ^^^^^^^^^^^^^^^^^^^^^^^^^^^^^^^^^^^^^^^^^^^^^^^^^^^^^^^^^^^^^^^^^
  File "c:\Users\andre\CascadeProjects\windsurf-project\ccwithai-chatbot\app.py", line 84, in chat
    except openai.error.OpenAIError as e:
           ^^^^^^^^^^^^
AttributeError: module 'openai' has no attribute 'error'
2024-11-20 21:11:30,437 - INFO - 127.0.0.1 - - [20/Nov/2024 21:11:30] "[35m[1mPOST /api/chat HTTP/1.1[0m" 500 -
2024-11-20 21:11:37,614 - INFO - 127.0.0.1 - - [20/Nov/2024 21:11:37] "[36mGET / HTTP/1.1[0m" 304 -
2024-11-20 21:11:37,672 - ERROR - Error occurred: 404 Not Found: The requested URL was not found on the server. If you entered the URL manually please check your spelling and try again.
Traceback (most recent call last):
  File "C:\Users\andre\AppData\Local\Packages\PythonSoftwareFoundation.Python.3.11_qbz5n2kfra8p0\LocalCache\local-packages\Python311\site-packages\flask\app.py", line 917, in full_dispatch_request
    rv = self.dispatch_request()
         ^^^^^^^^^^^^^^^^^^^^^^^
  File "C:\Users\andre\AppData\Local\Packages\PythonSoftwareFoundation.Python.3.11_qbz5n2kfra8p0\LocalCache\local-packages\Python311\site-packages\flask\app.py", line 902, in dispatch_request
    return self.ensure_sync(self.view_functions[rule.endpoint])(**view_args)  # type: ignore[no-any-return]
           ^^^^^^^^^^^^^^^^^^^^^^^^^^^^^^^^^^^^^^^^^^^^^^^^^^^^^^^^^^^^^^^^^
  File "C:\Users\andre\AppData\Local\Packages\PythonSoftwareFoundation.Python.3.11_qbz5n2kfra8p0\LocalCache\local-packages\Python311\site-packages\flask\app.py", line 278, in <lambda>
    view_func=lambda **kw: self_ref().send_static_file(**kw),  # type: ignore # noqa: B950
                           ^^^^^^^^^^^^^^^^^^^^^^^^^^^^^^^^^
  File "C:\Users\andre\AppData\Local\Packages\PythonSoftwareFoundation.Python.3.11_qbz5n2kfra8p0\LocalCache\local-packages\Python311\site-packages\flask\app.py", line 326, in send_static_file
    return send_from_directory(
           ^^^^^^^^^^^^^^^^^^^^
  File "C:\Users\andre\AppData\Local\Packages\PythonSoftwareFoundation.Python.3.11_qbz5n2kfra8p0\LocalCache\local-packages\Python311\site-packages\flask\helpers.py", line 565, in send_from_directory
    return werkzeug.utils.send_from_directory(  # type: ignore[return-value]
           ^^^^^^^^^^^^^^^^^^^^^^^^^^^^^^^^^^^^^^^^^^^^^^^^^^^^^^^^^^^^^^^^^
  File "C:\Users\andre\AppData\Local\Packages\PythonSoftwareFoundation.Python.3.11_qbz5n2kfra8p0\LocalCache\local-packages\Python311\site-packages\werkzeug\utils.py", line 575, in send_from_directory
    raise NotFound()
werkzeug.exceptions.NotFound: 404 Not Found: The requested URL was not found on the server. If you entered the URL manually please check your spelling and try again.
2024-11-20 21:11:37,672 - INFO - 127.0.0.1 - - [20/Nov/2024 21:11:37] "[35m[1mGET /favicon.ico HTTP/1.1[0m" 500 -
2024-11-20 21:11:41,312 - INFO - Chat request received - length: 2
2024-11-20 21:11:41,312 - ERROR - Error occurred: module 'openai' has no attribute 'error'
Traceback (most recent call last):
  File "c:\Users\andre\CascadeProjects\windsurf-project\ccwithai-chatbot\app.py", line 65, in chat
    response = openai.ChatCompletion.create(
               ^^^^^^^^^^^^^^^^^^^^^^^^^^^^
  File "C:\Users\andre\AppData\Local\Packages\PythonSoftwareFoundation.Python.3.11_qbz5n2kfra8p0\LocalCache\local-packages\Python311\site-packages\openai\_utils\_proxy.py", line 22, in __getattr__
    return getattr(self.__get_proxied__(), attr)
                   ^^^^^^^^^^^^^^^^^^^^^^
  File "C:\Users\andre\AppData\Local\Packages\PythonSoftwareFoundation.Python.3.11_qbz5n2kfra8p0\LocalCache\local-packages\Python311\site-packages\openai\_utils\_proxy.py", line 43, in __get_proxied__
    return self.__load__()
           ^^^^^^^^^^^^^^^
  File "C:\Users\andre\AppData\Local\Packages\PythonSoftwareFoundation.Python.3.11_qbz5n2kfra8p0\LocalCache\local-packages\Python311\site-packages\openai\lib\_old_api.py", line 33, in __load__
    raise APIRemovedInV1(symbol=self._symbol)
openai.lib._old_api.APIRemovedInV1: 

You tried to access openai.ChatCompletion, but this is no longer supported in openai>=1.0.0 - see the README at https://github.com/openai/openai-python for the API.

You can run `openai migrate` to automatically upgrade your codebase to use the 1.0.0 interface. 

Alternatively, you can pin your installation to the old version, e.g. `pip install openai==0.28`

A detailed migration guide is available here: https://github.com/openai/openai-python/discussions/742


During handling of the above exception, another exception occurred:

Traceback (most recent call last):
  File "C:\Users\andre\AppData\Local\Packages\PythonSoftwareFoundation.Python.3.11_qbz5n2kfra8p0\LocalCache\local-packages\Python311\site-packages\flask\app.py", line 917, in full_dispatch_request
    rv = self.dispatch_request()
         ^^^^^^^^^^^^^^^^^^^^^^^
  File "C:\Users\andre\AppData\Local\Packages\PythonSoftwareFoundation.Python.3.11_qbz5n2kfra8p0\LocalCache\local-packages\Python311\site-packages\flask\app.py", line 902, in dispatch_request
    return self.ensure_sync(self.view_functions[rule.endpoint])(**view_args)  # type: ignore[no-any-return]
           ^^^^^^^^^^^^^^^^^^^^^^^^^^^^^^^^^^^^^^^^^^^^^^^^^^^^^^^^^^^^^^^^^
  File "c:\Users\andre\CascadeProjects\windsurf-project\ccwithai-chatbot\app.py", line 84, in chat
    except openai.error.OpenAIError as e:
           ^^^^^^^^^^^^
AttributeError: module 'openai' has no attribute 'error'
2024-11-20 21:11:41,312 - INFO - 127.0.0.1 - - [20/Nov/2024 21:11:41] "[35m[1mPOST /api/chat HTTP/1.1[0m" 500 -
2024-11-20 21:13:04,049 - INFO - [31m[1mWARNING: This is a development server. Do not use it in a production deployment. Use a production WSGI server instead.[0m
 * Running on http://127.0.0.1:5000
2024-11-20 21:13:04,049 - INFO - [33mPress CTRL+C to quit[0m
2024-11-20 21:13:15,253 - INFO - 127.0.0.1 - - [20/Nov/2024 21:13:15] "[36mGET / HTTP/1.1[0m" 304 -
2024-11-20 21:13:15,286 - ERROR - Error occurred: 404 Not Found: The requested URL was not found on the server. If you entered the URL manually please check your spelling and try again.
Traceback (most recent call last):
  File "C:\Users\andre\AppData\Local\Packages\PythonSoftwareFoundation.Python.3.11_qbz5n2kfra8p0\LocalCache\local-packages\Python311\site-packages\flask\app.py", line 917, in full_dispatch_request
    rv = self.dispatch_request()
         ^^^^^^^^^^^^^^^^^^^^^^^
  File "C:\Users\andre\AppData\Local\Packages\PythonSoftwareFoundation.Python.3.11_qbz5n2kfra8p0\LocalCache\local-packages\Python311\site-packages\flask\app.py", line 902, in dispatch_request
    return self.ensure_sync(self.view_functions[rule.endpoint])(**view_args)  # type: ignore[no-any-return]
           ^^^^^^^^^^^^^^^^^^^^^^^^^^^^^^^^^^^^^^^^^^^^^^^^^^^^^^^^^^^^^^^^^
  File "C:\Users\andre\AppData\Local\Packages\PythonSoftwareFoundation.Python.3.11_qbz5n2kfra8p0\LocalCache\local-packages\Python311\site-packages\flask\app.py", line 278, in <lambda>
    view_func=lambda **kw: self_ref().send_static_file(**kw),  # type: ignore # noqa: B950
                           ^^^^^^^^^^^^^^^^^^^^^^^^^^^^^^^^^
  File "C:\Users\andre\AppData\Local\Packages\PythonSoftwareFoundation.Python.3.11_qbz5n2kfra8p0\LocalCache\local-packages\Python311\site-packages\flask\app.py", line 326, in send_static_file
    return send_from_directory(
           ^^^^^^^^^^^^^^^^^^^^
  File "C:\Users\andre\AppData\Local\Packages\PythonSoftwareFoundation.Python.3.11_qbz5n2kfra8p0\LocalCache\local-packages\Python311\site-packages\flask\helpers.py", line 565, in send_from_directory
    return werkzeug.utils.send_from_directory(  # type: ignore[return-value]
           ^^^^^^^^^^^^^^^^^^^^^^^^^^^^^^^^^^^^^^^^^^^^^^^^^^^^^^^^^^^^^^^^^
  File "C:\Users\andre\AppData\Local\Packages\PythonSoftwareFoundation.Python.3.11_qbz5n2kfra8p0\LocalCache\local-packages\Python311\site-packages\werkzeug\utils.py", line 575, in send_from_directory
    raise NotFound()
werkzeug.exceptions.NotFound: 404 Not Found: The requested URL was not found on the server. If you entered the URL manually please check your spelling and try again.
2024-11-20 21:13:15,289 - INFO - 127.0.0.1 - - [20/Nov/2024 21:13:15] "[35m[1mGET /favicon.ico HTTP/1.1[0m" 500 -
2024-11-20 21:13:27,964 - INFO - Chat request received - length: 2
2024-11-20 21:13:27,966 - ERROR - Error occurred: module 'openai' has no attribute 'error'
Traceback (most recent call last):
  File "c:\Users\andre\CascadeProjects\windsurf-project\ccwithai-chatbot\app.py", line 65, in chat
    response = openai.ChatCompletion.create(
               ^^^^^^^^^^^^^^^^^^^^^^^^^^^^
  File "C:\Users\andre\AppData\Local\Packages\PythonSoftwareFoundation.Python.3.11_qbz5n2kfra8p0\LocalCache\local-packages\Python311\site-packages\openai\_utils\_proxy.py", line 22, in __getattr__
  File "C:\Users\andre\AppData\Local\Packages\PythonSoftwareFoundation.Python.3.11_qbz5n2kfra8p0\LocalCache\local-packages\Python311\site-packages\openai\_utils\_proxy.py", line 43, in __get_proxied__
  File "C:\Users\andre\AppData\Local\Packages\PythonSoftwareFoundation.Python.3.11_qbz5n2kfra8p0\LocalCache\local-packages\Python311\site-packages\openai\lib\_old_api.py", line 33, in __load__
openai.lib._old_api.APIRemovedInV1: 

You tried to access openai.ChatCompletion, but this is no longer supported in openai>=1.0.0 - see the README at https://github.com/openai/openai-python for the API.

You can run `openai migrate` to automatically upgrade your codebase to use the 1.0.0 interface. 

Alternatively, you can pin your installation to the old version, e.g. `pip install openai==0.28`

A detailed migration guide is available here: https://github.com/openai/openai-python/discussions/742


During handling of the above exception, another exception occurred:

Traceback (most recent call last):
  File "C:\Users\andre\AppData\Local\Packages\PythonSoftwareFoundation.Python.3.11_qbz5n2kfra8p0\LocalCache\local-packages\Python311\site-packages\flask\app.py", line 917, in full_dispatch_request
    rv = self.dispatch_request()
         ^^^^^^^^^^^^^^^^^^^^^^^
  File "C:\Users\andre\AppData\Local\Packages\PythonSoftwareFoundation.Python.3.11_qbz5n2kfra8p0\LocalCache\local-packages\Python311\site-packages\flask\app.py", line 902, in dispatch_request
    return self.ensure_sync(self.view_functions[rule.endpoint])(**view_args)  # type: ignore[no-any-return]
           ^^^^^^^^^^^^^^^^^^^^^^^^^^^^^^^^^^^^^^^^^^^^^^^^^^^^^^^^^^^^^^^^^
  File "c:\Users\andre\CascadeProjects\windsurf-project\ccwithai-chatbot\app.py", line 84, in chat
    except openai.error.OpenAIError as e:
           ^^^^^^^^^^^^
AttributeError: module 'openai' has no attribute 'error'
2024-11-20 21:13:27,967 - INFO - 127.0.0.1 - - [20/Nov/2024 21:13:27] "[35m[1mPOST /api/chat HTTP/1.1[0m" 500 -
2024-11-20 21:13:51,818 - INFO - 127.0.0.1 - - [20/Nov/2024 21:13:51] "[36mGET / HTTP/1.1[0m" 304 -
2024-11-20 21:13:51,873 - ERROR - Error occurred: 404 Not Found: The requested URL was not found on the server. If you entered the URL manually please check your spelling and try again.
Traceback (most recent call last):
  File "C:\Users\andre\AppData\Local\Packages\PythonSoftwareFoundation.Python.3.11_qbz5n2kfra8p0\LocalCache\local-packages\Python311\site-packages\flask\app.py", line 917, in full_dispatch_request
    rv = self.dispatch_request()
         ^^^^^^^^^^^^^^^^^^^^^^^
  File "C:\Users\andre\AppData\Local\Packages\PythonSoftwareFoundation.Python.3.11_qbz5n2kfra8p0\LocalCache\local-packages\Python311\site-packages\flask\app.py", line 902, in dispatch_request
    return self.ensure_sync(self.view_functions[rule.endpoint])(**view_args)  # type: ignore[no-any-return]
           ^^^^^^^^^^^^^^^^^^^^^^^^^^^^^^^^^^^^^^^^^^^^^^^^^^^^^^^^^^^^^^^^^
  File "C:\Users\andre\AppData\Local\Packages\PythonSoftwareFoundation.Python.3.11_qbz5n2kfra8p0\LocalCache\local-packages\Python311\site-packages\flask\app.py", line 278, in <lambda>
    view_func=lambda **kw: self_ref().send_static_file(**kw),  # type: ignore # noqa: B950
                           ^^^^^^^^^^^^^^^^^^^^^^^^^^^^^^^^^
  File "C:\Users\andre\AppData\Local\Packages\PythonSoftwareFoundation.Python.3.11_qbz5n2kfra8p0\LocalCache\local-packages\Python311\site-packages\flask\app.py", line 326, in send_static_file
    return send_from_directory(
           ^^^^^^^^^^^^^^^^^^^^
  File "C:\Users\andre\AppData\Local\Packages\PythonSoftwareFoundation.Python.3.11_qbz5n2kfra8p0\LocalCache\local-packages\Python311\site-packages\flask\helpers.py", line 565, in send_from_directory
    return werkzeug.utils.send_from_directory(  # type: ignore[return-value]
           ^^^^^^^^^^^^^^^^^^^^^^^^^^^^^^^^^^^^^^^^^^^^^^^^^^^^^^^^^^^^^^^^^
  File "C:\Users\andre\AppData\Local\Packages\PythonSoftwareFoundation.Python.3.11_qbz5n2kfra8p0\LocalCache\local-packages\Python311\site-packages\werkzeug\utils.py", line 575, in send_from_directory
    raise NotFound()
werkzeug.exceptions.NotFound: 404 Not Found: The requested URL was not found on the server. If you entered the URL manually please check your spelling and try again.
2024-11-20 21:13:51,874 - INFO - 127.0.0.1 - - [20/Nov/2024 21:13:51] "[35m[1mGET /favicon.ico HTTP/1.1[0m" 500 -
2024-11-20 21:13:55,307 - INFO - Chat request received - length: 2
2024-11-20 21:13:55,308 - ERROR - Error occurred: module 'openai' has no attribute 'error'
Traceback (most recent call last):
  File "c:\Users\andre\CascadeProjects\windsurf-project\ccwithai-chatbot\app.py", line 65, in chat
    response = openai.ChatCompletion.create(
               ^^^^^^^^^^^^^^^^^^^^^^^^^^^^
  File "C:\Users\andre\AppData\Local\Packages\PythonSoftwareFoundation.Python.3.11_qbz5n2kfra8p0\LocalCache\local-packages\Python311\site-packages\openai\_utils\_proxy.py", line 22, in __getattr__
  File "C:\Users\andre\AppData\Local\Packages\PythonSoftwareFoundation.Python.3.11_qbz5n2kfra8p0\LocalCache\local-packages\Python311\site-packages\openai\_utils\_proxy.py", line 43, in __get_proxied__
  File "C:\Users\andre\AppData\Local\Packages\PythonSoftwareFoundation.Python.3.11_qbz5n2kfra8p0\LocalCache\local-packages\Python311\site-packages\openai\lib\_old_api.py", line 33, in __load__
openai.lib._old_api.APIRemovedInV1: 

You tried to access openai.ChatCompletion, but this is no longer supported in openai>=1.0.0 - see the README at https://github.com/openai/openai-python for the API.

You can run `openai migrate` to automatically upgrade your codebase to use the 1.0.0 interface. 

Alternatively, you can pin your installation to the old version, e.g. `pip install openai==0.28`

A detailed migration guide is available here: https://github.com/openai/openai-python/discussions/742


During handling of the above exception, another exception occurred:

Traceback (most recent call last):
  File "C:\Users\andre\AppData\Local\Packages\PythonSoftwareFoundation.Python.3.11_qbz5n2kfra8p0\LocalCache\local-packages\Python311\site-packages\flask\app.py", line 917, in full_dispatch_request
    rv = self.dispatch_request()
         ^^^^^^^^^^^^^^^^^^^^^^^
  File "C:\Users\andre\AppData\Local\Packages\PythonSoftwareFoundation.Python.3.11_qbz5n2kfra8p0\LocalCache\local-packages\Python311\site-packages\flask\app.py", line 902, in dispatch_request
    return self.ensure_sync(self.view_functions[rule.endpoint])(**view_args)  # type: ignore[no-any-return]
           ^^^^^^^^^^^^^^^^^^^^^^^^^^^^^^^^^^^^^^^^^^^^^^^^^^^^^^^^^^^^^^^^^
  File "c:\Users\andre\CascadeProjects\windsurf-project\ccwithai-chatbot\app.py", line 84, in chat
    except openai.error.OpenAIError as e:
           ^^^^^^^^^^^^
AttributeError: module 'openai' has no attribute 'error'
2024-11-20 21:13:55,308 - INFO - 127.0.0.1 - - [20/Nov/2024 21:13:55] "[35m[1mPOST /api/chat HTTP/1.1[0m" 500 -
2024-11-20 21:15:26,166 - INFO - [31m[1mWARNING: This is a development server. Do not use it in a production deployment. Use a production WSGI server instead.[0m
 * Running on http://127.0.0.1:5000
2024-11-20 21:15:26,166 - INFO - [33mPress CTRL+C to quit[0m
2024-11-20 21:15:52,967 - INFO - 127.0.0.1 - - [20/Nov/2024 21:15:52] "[36mGET / HTTP/1.1[0m" 304 -
2024-11-20 21:15:53,025 - ERROR - Error occurred: 404 Not Found: The requested URL was not found on the server. If you entered the URL manually please check your spelling and try again.
Traceback (most recent call last):
  File "C:\Users\andre\AppData\Local\Packages\PythonSoftwareFoundation.Python.3.11_qbz5n2kfra8p0\LocalCache\local-packages\Python311\site-packages\flask\app.py", line 917, in full_dispatch_request
    rv = self.dispatch_request()
         ^^^^^^^^^^^^^^^^^^^^^^^
  File "C:\Users\andre\AppData\Local\Packages\PythonSoftwareFoundation.Python.3.11_qbz5n2kfra8p0\LocalCache\local-packages\Python311\site-packages\flask\app.py", line 902, in dispatch_request
    return self.ensure_sync(self.view_functions[rule.endpoint])(**view_args)  # type: ignore[no-any-return]
           ^^^^^^^^^^^^^^^^^^^^^^^^^^^^^^^^^^^^^^^^^^^^^^^^^^^^^^^^^^^^^^^^^
  File "C:\Users\andre\AppData\Local\Packages\PythonSoftwareFoundation.Python.3.11_qbz5n2kfra8p0\LocalCache\local-packages\Python311\site-packages\flask\app.py", line 278, in <lambda>
    view_func=lambda **kw: self_ref().send_static_file(**kw),  # type: ignore # noqa: B950
                           ^^^^^^^^^^^^^^^^^^^^^^^^^^^^^^^^^
  File "C:\Users\andre\AppData\Local\Packages\PythonSoftwareFoundation.Python.3.11_qbz5n2kfra8p0\LocalCache\local-packages\Python311\site-packages\flask\app.py", line 326, in send_static_file
    return send_from_directory(
           ^^^^^^^^^^^^^^^^^^^^
  File "C:\Users\andre\AppData\Local\Packages\PythonSoftwareFoundation.Python.3.11_qbz5n2kfra8p0\LocalCache\local-packages\Python311\site-packages\flask\helpers.py", line 565, in send_from_directory
    return werkzeug.utils.send_from_directory(  # type: ignore[return-value]
           ^^^^^^^^^^^^^^^^^^^^^^^^^^^^^^^^^^^^^^^^^^^^^^^^^^^^^^^^^^^^^^^^^
  File "C:\Users\andre\AppData\Local\Packages\PythonSoftwareFoundation.Python.3.11_qbz5n2kfra8p0\LocalCache\local-packages\Python311\site-packages\werkzeug\utils.py", line 575, in send_from_directory
    raise NotFound()
werkzeug.exceptions.NotFound: 404 Not Found: The requested URL was not found on the server. If you entered the URL manually please check your spelling and try again.
2024-11-20 21:15:53,026 - INFO - 127.0.0.1 - - [20/Nov/2024 21:15:53] "[35m[1mGET /favicon.ico HTTP/1.1[0m" 500 -
2024-11-20 21:15:56,204 - INFO - Chat request received - length: 2
2024-11-20 21:15:56,206 - ERROR - Error occurred: module 'openai' has no attribute 'error'
Traceback (most recent call last):
  File "c:\Users\andre\CascadeProjects\windsurf-project\ccwithai-chatbot\app.py", line 65, in chat
    app.logger.info(f"Knowledge base loaded: {json.dumps(knowledge_base)[:200]}...")
               ^^^^^^^^^^^^^^^^^^^^^^^^^^^^
  File "C:\Users\andre\AppData\Local\Packages\PythonSoftwareFoundation.Python.3.11_qbz5n2kfra8p0\LocalCache\local-packages\Python311\site-packages\openai\_utils\_proxy.py", line 22, in __getattr__
  File "C:\Users\andre\AppData\Local\Packages\PythonSoftwareFoundation.Python.3.11_qbz5n2kfra8p0\LocalCache\local-packages\Python311\site-packages\openai\_utils\_proxy.py", line 43, in __get_proxied__
  File "C:\Users\andre\AppData\Local\Packages\PythonSoftwareFoundation.Python.3.11_qbz5n2kfra8p0\LocalCache\local-packages\Python311\site-packages\openai\lib\_old_api.py", line 33, in __load__
openai.lib._old_api.APIRemovedInV1: 

You tried to access openai.ChatCompletion, but this is no longer supported in openai>=1.0.0 - see the README at https://github.com/openai/openai-python for the API.

You can run `openai migrate` to automatically upgrade your codebase to use the 1.0.0 interface. 

Alternatively, you can pin your installation to the old version, e.g. `pip install openai==0.28`

A detailed migration guide is available here: https://github.com/openai/openai-python/discussions/742


During handling of the above exception, another exception occurred:

Traceback (most recent call last):
  File "C:\Users\andre\AppData\Local\Packages\PythonSoftwareFoundation.Python.3.11_qbz5n2kfra8p0\LocalCache\local-packages\Python311\site-packages\flask\app.py", line 917, in full_dispatch_request
    rv = self.dispatch_request()
         ^^^^^^^^^^^^^^^^^^^^^^^
  File "C:\Users\andre\AppData\Local\Packages\PythonSoftwareFoundation.Python.3.11_qbz5n2kfra8p0\LocalCache\local-packages\Python311\site-packages\flask\app.py", line 902, in dispatch_request
    return self.ensure_sync(self.view_functions[rule.endpoint])(**view_args)  # type: ignore[no-any-return]
           ^^^^^^^^^^^^^^^^^^^^^^^^^^^^^^^^^^^^^^^^^^^^^^^^^^^^^^^^^^^^^^^^^
  File "c:\Users\andre\CascadeProjects\windsurf-project\ccwithai-chatbot\app.py", line 84, in chat
    assistant_message = response['choices'][0]['message']['content']
       ^^^^^^^^^^^^
AttributeError: module 'openai' has no attribute 'error'
2024-11-20 21:15:56,209 - INFO - 127.0.0.1 - - [20/Nov/2024 21:15:56] "[35m[1mPOST /api/chat HTTP/1.1[0m" 500 -
2024-11-20 21:16:01,626 - INFO - Chat request received - length: 9
2024-11-20 21:16:01,628 - ERROR - Error occurred: module 'openai' has no attribute 'error'
Traceback (most recent call last):
  File "c:\Users\andre\CascadeProjects\windsurf-project\ccwithai-chatbot\app.py", line 65, in chat
    app.logger.info(f"Knowledge base loaded: {json.dumps(knowledge_base)[:200]}...")
               ^^^^^^^^^^^^^^^^^^^^^^^^^^^^
  File "C:\Users\andre\AppData\Local\Packages\PythonSoftwareFoundation.Python.3.11_qbz5n2kfra8p0\LocalCache\local-packages\Python311\site-packages\openai\_utils\_proxy.py", line 22, in __getattr__
  File "C:\Users\andre\AppData\Local\Packages\PythonSoftwareFoundation.Python.3.11_qbz5n2kfra8p0\LocalCache\local-packages\Python311\site-packages\openai\_utils\_proxy.py", line 43, in __get_proxied__
  File "C:\Users\andre\AppData\Local\Packages\PythonSoftwareFoundation.Python.3.11_qbz5n2kfra8p0\LocalCache\local-packages\Python311\site-packages\openai\lib\_old_api.py", line 33, in __load__
openai.lib._old_api.APIRemovedInV1: 

You tried to access openai.ChatCompletion, but this is no longer supported in openai>=1.0.0 - see the README at https://github.com/openai/openai-python for the API.

You can run `openai migrate` to automatically upgrade your codebase to use the 1.0.0 interface. 

Alternatively, you can pin your installation to the old version, e.g. `pip install openai==0.28`

A detailed migration guide is available here: https://github.com/openai/openai-python/discussions/742


During handling of the above exception, another exception occurred:

Traceback (most recent call last):
  File "C:\Users\andre\AppData\Local\Packages\PythonSoftwareFoundation.Python.3.11_qbz5n2kfra8p0\LocalCache\local-packages\Python311\site-packages\flask\app.py", line 917, in full_dispatch_request
    rv = self.dispatch_request()
         ^^^^^^^^^^^^^^^^^^^^^^^
  File "C:\Users\andre\AppData\Local\Packages\PythonSoftwareFoundation.Python.3.11_qbz5n2kfra8p0\LocalCache\local-packages\Python311\site-packages\flask\app.py", line 902, in dispatch_request
    return self.ensure_sync(self.view_functions[rule.endpoint])(**view_args)  # type: ignore[no-any-return]
           ^^^^^^^^^^^^^^^^^^^^^^^^^^^^^^^^^^^^^^^^^^^^^^^^^^^^^^^^^^^^^^^^^
  File "c:\Users\andre\CascadeProjects\windsurf-project\ccwithai-chatbot\app.py", line 84, in chat
    assistant_message = response['choices'][0]['message']['content']
       ^^^^^^^^^^^^
AttributeError: module 'openai' has no attribute 'error'
2024-11-20 21:16:01,629 - INFO - 127.0.0.1 - - [20/Nov/2024 21:16:01] "[35m[1mPOST /api/chat HTTP/1.1[0m" 500 -
2024-11-20 21:17:08,605 - INFO - [31m[1mWARNING: This is a development server. Do not use it in a production deployment. Use a production WSGI server instead.[0m
 * Running on http://127.0.0.1:5000
2024-11-20 21:17:08,605 - INFO - [33mPress CTRL+C to quit[0m
2024-11-20 21:17:17,589 - INFO - 127.0.0.1 - - [20/Nov/2024 21:17:17] "[36mGET / HTTP/1.1[0m" 304 -
2024-11-20 21:17:17,628 - ERROR - Error occurred: 404 Not Found: The requested URL was not found on the server. If you entered the URL manually please check your spelling and try again.
Traceback (most recent call last):
  File "C:\Users\andre\AppData\Local\Packages\PythonSoftwareFoundation.Python.3.11_qbz5n2kfra8p0\LocalCache\local-packages\Python311\site-packages\flask\app.py", line 917, in full_dispatch_request
    rv = self.dispatch_request()
         ^^^^^^^^^^^^^^^^^^^^^^^
  File "C:\Users\andre\AppData\Local\Packages\PythonSoftwareFoundation.Python.3.11_qbz5n2kfra8p0\LocalCache\local-packages\Python311\site-packages\flask\app.py", line 902, in dispatch_request
    return self.ensure_sync(self.view_functions[rule.endpoint])(**view_args)  # type: ignore[no-any-return]
           ^^^^^^^^^^^^^^^^^^^^^^^^^^^^^^^^^^^^^^^^^^^^^^^^^^^^^^^^^^^^^^^^^
  File "C:\Users\andre\AppData\Local\Packages\PythonSoftwareFoundation.Python.3.11_qbz5n2kfra8p0\LocalCache\local-packages\Python311\site-packages\flask\app.py", line 278, in <lambda>
    view_func=lambda **kw: self_ref().send_static_file(**kw),  # type: ignore # noqa: B950
                           ^^^^^^^^^^^^^^^^^^^^^^^^^^^^^^^^^
  File "C:\Users\andre\AppData\Local\Packages\PythonSoftwareFoundation.Python.3.11_qbz5n2kfra8p0\LocalCache\local-packages\Python311\site-packages\flask\app.py", line 326, in send_static_file
    return send_from_directory(
           ^^^^^^^^^^^^^^^^^^^^
  File "C:\Users\andre\AppData\Local\Packages\PythonSoftwareFoundation.Python.3.11_qbz5n2kfra8p0\LocalCache\local-packages\Python311\site-packages\flask\helpers.py", line 565, in send_from_directory
    return werkzeug.utils.send_from_directory(  # type: ignore[return-value]
           ^^^^^^^^^^^^^^^^^^^^^^^^^^^^^^^^^^^^^^^^^^^^^^^^^^^^^^^^^^^^^^^^^
  File "C:\Users\andre\AppData\Local\Packages\PythonSoftwareFoundation.Python.3.11_qbz5n2kfra8p0\LocalCache\local-packages\Python311\site-packages\werkzeug\utils.py", line 575, in send_from_directory
    raise NotFound()
werkzeug.exceptions.NotFound: 404 Not Found: The requested URL was not found on the server. If you entered the URL manually please check your spelling and try again.
2024-11-20 21:17:17,629 - INFO - 127.0.0.1 - - [20/Nov/2024 21:17:17] "[35m[1mGET /favicon.ico HTTP/1.1[0m" 500 -
2024-11-20 21:17:20,560 - INFO - Chat request received - length: 2
2024-11-20 21:17:20,560 - ERROR - Error occurred: module 'openai' has no attribute 'error'
Traceback (most recent call last):
  File "c:\Users\andre\CascadeProjects\windsurf-project\ccwithai-chatbot\app.py", line 65, in chat
    app.logger.info(f"Knowledge base loaded: {json.dumps(knowledge_base)[:200]}...")
               ^^^^^^^^^^^^^^^^^^^^^^^^^^^^
  File "C:\Users\andre\AppData\Local\Packages\PythonSoftwareFoundation.Python.3.11_qbz5n2kfra8p0\LocalCache\local-packages\Python311\site-packages\openai\_utils\_proxy.py", line 22, in __getattr__
  File "C:\Users\andre\AppData\Local\Packages\PythonSoftwareFoundation.Python.3.11_qbz5n2kfra8p0\LocalCache\local-packages\Python311\site-packages\openai\_utils\_proxy.py", line 43, in __get_proxied__
  File "C:\Users\andre\AppData\Local\Packages\PythonSoftwareFoundation.Python.3.11_qbz5n2kfra8p0\LocalCache\local-packages\Python311\site-packages\openai\lib\_old_api.py", line 33, in __load__
openai.lib._old_api.APIRemovedInV1: 

You tried to access openai.ChatCompletion, but this is no longer supported in openai>=1.0.0 - see the README at https://github.com/openai/openai-python for the API.

You can run `openai migrate` to automatically upgrade your codebase to use the 1.0.0 interface. 

Alternatively, you can pin your installation to the old version, e.g. `pip install openai==0.28`

A detailed migration guide is available here: https://github.com/openai/openai-python/discussions/742


During handling of the above exception, another exception occurred:

Traceback (most recent call last):
  File "C:\Users\andre\AppData\Local\Packages\PythonSoftwareFoundation.Python.3.11_qbz5n2kfra8p0\LocalCache\local-packages\Python311\site-packages\flask\app.py", line 917, in full_dispatch_request
    rv = self.dispatch_request()
         ^^^^^^^^^^^^^^^^^^^^^^^
  File "C:\Users\andre\AppData\Local\Packages\PythonSoftwareFoundation.Python.3.11_qbz5n2kfra8p0\LocalCache\local-packages\Python311\site-packages\flask\app.py", line 902, in dispatch_request
    return self.ensure_sync(self.view_functions[rule.endpoint])(**view_args)  # type: ignore[no-any-return]
           ^^^^^^^^^^^^^^^^^^^^^^^^^^^^^^^^^^^^^^^^^^^^^^^^^^^^^^^^^^^^^^^^^
  File "c:\Users\andre\CascadeProjects\windsurf-project\ccwithai-chatbot\app.py", line 84, in chat
AttributeError: module 'openai' has no attribute 'error'
2024-11-20 21:17:20,562 - INFO - 127.0.0.1 - - [20/Nov/2024 21:17:20] "[35m[1mPOST /api/chat HTTP/1.1[0m" 500 -
2024-11-20 21:17:39,641 - INFO - 127.0.0.1 - - [20/Nov/2024 21:17:39] "[36mGET / HTTP/1.1[0m" 304 -
2024-11-20 21:17:39,694 - ERROR - Error occurred: 404 Not Found: The requested URL was not found on the server. If you entered the URL manually please check your spelling and try again.
Traceback (most recent call last):
  File "C:\Users\andre\AppData\Local\Packages\PythonSoftwareFoundation.Python.3.11_qbz5n2kfra8p0\LocalCache\local-packages\Python311\site-packages\flask\app.py", line 917, in full_dispatch_request
    rv = self.dispatch_request()
         ^^^^^^^^^^^^^^^^^^^^^^^
  File "C:\Users\andre\AppData\Local\Packages\PythonSoftwareFoundation.Python.3.11_qbz5n2kfra8p0\LocalCache\local-packages\Python311\site-packages\flask\app.py", line 902, in dispatch_request
    return self.ensure_sync(self.view_functions[rule.endpoint])(**view_args)  # type: ignore[no-any-return]
           ^^^^^^^^^^^^^^^^^^^^^^^^^^^^^^^^^^^^^^^^^^^^^^^^^^^^^^^^^^^^^^^^^
  File "C:\Users\andre\AppData\Local\Packages\PythonSoftwareFoundation.Python.3.11_qbz5n2kfra8p0\LocalCache\local-packages\Python311\site-packages\flask\app.py", line 278, in <lambda>
    view_func=lambda **kw: self_ref().send_static_file(**kw),  # type: ignore # noqa: B950
                           ^^^^^^^^^^^^^^^^^^^^^^^^^^^^^^^^^
  File "C:\Users\andre\AppData\Local\Packages\PythonSoftwareFoundation.Python.3.11_qbz5n2kfra8p0\LocalCache\local-packages\Python311\site-packages\flask\app.py", line 326, in send_static_file
    return send_from_directory(
           ^^^^^^^^^^^^^^^^^^^^
  File "C:\Users\andre\AppData\Local\Packages\PythonSoftwareFoundation.Python.3.11_qbz5n2kfra8p0\LocalCache\local-packages\Python311\site-packages\flask\helpers.py", line 565, in send_from_directory
    return werkzeug.utils.send_from_directory(  # type: ignore[return-value]
           ^^^^^^^^^^^^^^^^^^^^^^^^^^^^^^^^^^^^^^^^^^^^^^^^^^^^^^^^^^^^^^^^^
  File "C:\Users\andre\AppData\Local\Packages\PythonSoftwareFoundation.Python.3.11_qbz5n2kfra8p0\LocalCache\local-packages\Python311\site-packages\werkzeug\utils.py", line 575, in send_from_directory
    raise NotFound()
werkzeug.exceptions.NotFound: 404 Not Found: The requested URL was not found on the server. If you entered the URL manually please check your spelling and try again.
2024-11-20 21:17:39,697 - INFO - 127.0.0.1 - - [20/Nov/2024 21:17:39] "[35m[1mGET /favicon.ico HTTP/1.1[0m" 500 -
2024-11-20 21:17:42,838 - INFO - Chat request received - length: 2
2024-11-20 21:17:42,839 - ERROR - Error occurred: module 'openai' has no attribute 'error'
Traceback (most recent call last):
  File "c:\Users\andre\CascadeProjects\windsurf-project\ccwithai-chatbot\app.py", line 65, in chat
    app.logger.info(f"Knowledge base loaded: {json.dumps(knowledge_base)[:200]}...")
               ^^^^^^^^^^^^^^^^^^^^^^^^^^^^
  File "C:\Users\andre\AppData\Local\Packages\PythonSoftwareFoundation.Python.3.11_qbz5n2kfra8p0\LocalCache\local-packages\Python311\site-packages\openai\_utils\_proxy.py", line 22, in __getattr__
  File "C:\Users\andre\AppData\Local\Packages\PythonSoftwareFoundation.Python.3.11_qbz5n2kfra8p0\LocalCache\local-packages\Python311\site-packages\openai\_utils\_proxy.py", line 43, in __get_proxied__
  File "C:\Users\andre\AppData\Local\Packages\PythonSoftwareFoundation.Python.3.11_qbz5n2kfra8p0\LocalCache\local-packages\Python311\site-packages\openai\lib\_old_api.py", line 33, in __load__
openai.lib._old_api.APIRemovedInV1: 

You tried to access openai.ChatCompletion, but this is no longer supported in openai>=1.0.0 - see the README at https://github.com/openai/openai-python for the API.

You can run `openai migrate` to automatically upgrade your codebase to use the 1.0.0 interface. 

Alternatively, you can pin your installation to the old version, e.g. `pip install openai==0.28`

A detailed migration guide is available here: https://github.com/openai/openai-python/discussions/742


During handling of the above exception, another exception occurred:

Traceback (most recent call last):
  File "C:\Users\andre\AppData\Local\Packages\PythonSoftwareFoundation.Python.3.11_qbz5n2kfra8p0\LocalCache\local-packages\Python311\site-packages\flask\app.py", line 917, in full_dispatch_request
    rv = self.dispatch_request()
         ^^^^^^^^^^^^^^^^^^^^^^^
  File "C:\Users\andre\AppData\Local\Packages\PythonSoftwareFoundation.Python.3.11_qbz5n2kfra8p0\LocalCache\local-packages\Python311\site-packages\flask\app.py", line 902, in dispatch_request
    return self.ensure_sync(self.view_functions[rule.endpoint])(**view_args)  # type: ignore[no-any-return]
           ^^^^^^^^^^^^^^^^^^^^^^^^^^^^^^^^^^^^^^^^^^^^^^^^^^^^^^^^^^^^^^^^^
  File "c:\Users\andre\CascadeProjects\windsurf-project\ccwithai-chatbot\app.py", line 84, in chat
AttributeError: module 'openai' has no attribute 'error'
2024-11-20 21:17:42,839 - INFO - 127.0.0.1 - - [20/Nov/2024 21:17:42] "[35m[1mPOST /api/chat HTTP/1.1[0m" 500 -
2024-11-20 21:21:28,491 - INFO - Chat request received - length: 2
2024-11-20 21:21:28,491 - ERROR - Error occurred: module 'openai' has no attribute 'error'
Traceback (most recent call last):
  File "c:\Users\andre\CascadeProjects\windsurf-project\ccwithai-chatbot\app.py", line 65, in chat
    app.logger.info(f"Knowledge base loaded: {json.dumps(knowledge_base)[:200]}...")
               ^^^^^^^^^^^^^^^^^^^^^^^^^^^^
  File "C:\Users\andre\AppData\Local\Packages\PythonSoftwareFoundation.Python.3.11_qbz5n2kfra8p0\LocalCache\local-packages\Python311\site-packages\openai\_utils\_proxy.py", line 22, in __getattr__
  File "C:\Users\andre\AppData\Local\Packages\PythonSoftwareFoundation.Python.3.11_qbz5n2kfra8p0\LocalCache\local-packages\Python311\site-packages\openai\_utils\_proxy.py", line 43, in __get_proxied__
  File "C:\Users\andre\AppData\Local\Packages\PythonSoftwareFoundation.Python.3.11_qbz5n2kfra8p0\LocalCache\local-packages\Python311\site-packages\openai\lib\_old_api.py", line 33, in __load__
openai.lib._old_api.APIRemovedInV1: 

You tried to access openai.ChatCompletion, but this is no longer supported in openai>=1.0.0 - see the README at https://github.com/openai/openai-python for the API.

You can run `openai migrate` to automatically upgrade your codebase to use the 1.0.0 interface. 

Alternatively, you can pin your installation to the old version, e.g. `pip install openai==0.28`

A detailed migration guide is available here: https://github.com/openai/openai-python/discussions/742


During handling of the above exception, another exception occurred:

Traceback (most recent call last):
  File "C:\Users\andre\AppData\Local\Packages\PythonSoftwareFoundation.Python.3.11_qbz5n2kfra8p0\LocalCache\local-packages\Python311\site-packages\flask\app.py", line 917, in full_dispatch_request
    rv = self.dispatch_request()
         ^^^^^^^^^^^^^^^^^^^^^^^
  File "C:\Users\andre\AppData\Local\Packages\PythonSoftwareFoundation.Python.3.11_qbz5n2kfra8p0\LocalCache\local-packages\Python311\site-packages\flask\app.py", line 902, in dispatch_request
    return self.ensure_sync(self.view_functions[rule.endpoint])(**view_args)  # type: ignore[no-any-return]
           ^^^^^^^^^^^^^^^^^^^^^^^^^^^^^^^^^^^^^^^^^^^^^^^^^^^^^^^^^^^^^^^^^
  File "c:\Users\andre\CascadeProjects\windsurf-project\ccwithai-chatbot\app.py", line 84, in chat
AttributeError: module 'openai' has no attribute 'error'
2024-11-20 21:21:28,491 - INFO - 127.0.0.1 - - [20/Nov/2024 21:21:28] "[35m[1mPOST /api/chat HTTP/1.1[0m" 500 -
2024-11-20 21:24:07,601 - INFO - [31m[1mWARNING: This is a development server. Do not use it in a production deployment. Use a production WSGI server instead.[0m
 * Running on http://127.0.0.1:5000
2024-11-20 21:24:07,601 - INFO - [33mPress CTRL+C to quit[0m
2024-11-20 21:24:29,122 - INFO - 127.0.0.1 - - [20/Nov/2024 21:24:29] "[36mGET / HTTP/1.1[0m" 304 -
2024-11-20 21:24:29,175 - ERROR - Error occurred: 404 Not Found: The requested URL was not found on the server. If you entered the URL manually please check your spelling and try again.
Traceback (most recent call last):
  File "C:\Users\andre\AppData\Local\Packages\PythonSoftwareFoundation.Python.3.11_qbz5n2kfra8p0\LocalCache\local-packages\Python311\site-packages\flask\app.py", line 917, in full_dispatch_request
    rv = self.dispatch_request()
         ^^^^^^^^^^^^^^^^^^^^^^^
  File "C:\Users\andre\AppData\Local\Packages\PythonSoftwareFoundation.Python.3.11_qbz5n2kfra8p0\LocalCache\local-packages\Python311\site-packages\flask\app.py", line 902, in dispatch_request
    return self.ensure_sync(self.view_functions[rule.endpoint])(**view_args)  # type: ignore[no-any-return]
           ^^^^^^^^^^^^^^^^^^^^^^^^^^^^^^^^^^^^^^^^^^^^^^^^^^^^^^^^^^^^^^^^^
  File "C:\Users\andre\AppData\Local\Packages\PythonSoftwareFoundation.Python.3.11_qbz5n2kfra8p0\LocalCache\local-packages\Python311\site-packages\flask\app.py", line 278, in <lambda>
    view_func=lambda **kw: self_ref().send_static_file(**kw),  # type: ignore # noqa: B950
                           ^^^^^^^^^^^^^^^^^^^^^^^^^^^^^^^^^
  File "C:\Users\andre\AppData\Local\Packages\PythonSoftwareFoundation.Python.3.11_qbz5n2kfra8p0\LocalCache\local-packages\Python311\site-packages\flask\app.py", line 326, in send_static_file
    return send_from_directory(
           ^^^^^^^^^^^^^^^^^^^^
  File "C:\Users\andre\AppData\Local\Packages\PythonSoftwareFoundation.Python.3.11_qbz5n2kfra8p0\LocalCache\local-packages\Python311\site-packages\flask\helpers.py", line 565, in send_from_directory
    return werkzeug.utils.send_from_directory(  # type: ignore[return-value]
           ^^^^^^^^^^^^^^^^^^^^^^^^^^^^^^^^^^^^^^^^^^^^^^^^^^^^^^^^^^^^^^^^^
  File "C:\Users\andre\AppData\Local\Packages\PythonSoftwareFoundation.Python.3.11_qbz5n2kfra8p0\LocalCache\local-packages\Python311\site-packages\werkzeug\utils.py", line 575, in send_from_directory
    raise NotFound()
werkzeug.exceptions.NotFound: 404 Not Found: The requested URL was not found on the server. If you entered the URL manually please check your spelling and try again.
2024-11-20 21:24:29,177 - INFO - 127.0.0.1 - - [20/Nov/2024 21:24:29] "[35m[1mGET /favicon.ico HTTP/1.1[0m" 500 -
2024-11-20 21:24:32,489 - INFO - Chat request received - length: 2
2024-11-20 21:24:32,489 - ERROR - Error occurred: module 'openai' has no attribute 'error'
Traceback (most recent call last):
  File "c:\Users\andre\CascadeProjects\windsurf-project\ccwithai-chatbot\app.py", line 65, in chat
    app.logger.info("Context prepared for OpenAI...")
               ^^^^^^^^^^^^^^^^^^^^^^^^^^^^
  File "C:\Users\andre\AppData\Local\Packages\PythonSoftwareFoundation.Python.3.11_qbz5n2kfra8p0\LocalCache\local-packages\Python311\site-packages\openai\_utils\_proxy.py", line 22, in __getattr__
    return proxied  # pyright: ignore
               ^^^^^^^^^^^^^^^^^^^^^^
  File "C:\Users\andre\AppData\Local\Packages\PythonSoftwareFoundation.Python.3.11_qbz5n2kfra8p0\LocalCache\local-packages\Python311\site-packages\openai\_utils\_proxy.py", line 43, in __get_proxied__
    return []
           ^^^
  File "C:\Users\andre\AppData\Local\Packages\PythonSoftwareFoundation.Python.3.11_qbz5n2kfra8p0\LocalCache\local-packages\Python311\site-packages\openai\lib\_old_api.py", line 33, in __load__
    # return the proxy until it is eventually called so that
    ^^^^^^^^^^^^^^^^^^^^^^^^^^^^^^^^^^^^^^^^^
openai.lib._old_api.APIRemovedInV1: 

You tried to access openai.ChatCompletion, but this is no longer supported in openai>=1.0.0 - see the README at https://github.com/openai/openai-python for the API.

You can run `openai migrate` to automatically upgrade your codebase to use the 1.0.0 interface. 

Alternatively, you can pin your installation to the old version, e.g. `pip install openai==0.28`

A detailed migration guide is available here: https://github.com/openai/openai-python/discussions/742


During handling of the above exception, another exception occurred:

Traceback (most recent call last):
  File "C:\Users\andre\AppData\Local\Packages\PythonSoftwareFoundation.Python.3.11_qbz5n2kfra8p0\LocalCache\local-packages\Python311\site-packages\flask\app.py", line 917, in full_dispatch_request
    rv = self.dispatch_request()
         ^^^^^^^^^^^^^^^^^^^^^^^
  File "C:\Users\andre\AppData\Local\Packages\PythonSoftwareFoundation.Python.3.11_qbz5n2kfra8p0\LocalCache\local-packages\Python311\site-packages\flask\app.py", line 902, in dispatch_request
    return self.ensure_sync(self.view_functions[rule.endpoint])(**view_args)  # type: ignore[no-any-return]
           ^^^^^^^^^^^^^^^^^^^^^^^^^^^^^^^^^^^^^^^^^^^^^^^^^^^^^^^^^^^^^^^^^
  File "c:\Users\andre\CascadeProjects\windsurf-project\ccwithai-chatbot\app.py", line 84, in chat
    # Log successful response (without sensitive data)
    ^^^^^^^^^^^^
AttributeError: module 'openai' has no attribute 'error'
2024-11-20 21:24:32,489 - INFO - 127.0.0.1 - - [20/Nov/2024 21:24:32] "[35m[1mPOST /api/chat HTTP/1.1[0m" 500 -
2024-11-20 21:26:23,371 - INFO - 127.0.0.1 - - [20/Nov/2024 21:26:23] "[36mGET / HTTP/1.1[0m" 304 -
2024-11-20 21:26:23,411 - ERROR - Error occurred: 404 Not Found: The requested URL was not found on the server. If you entered the URL manually please check your spelling and try again.
Traceback (most recent call last):
  File "C:\Users\andre\AppData\Local\Packages\PythonSoftwareFoundation.Python.3.11_qbz5n2kfra8p0\LocalCache\local-packages\Python311\site-packages\flask\app.py", line 917, in full_dispatch_request
    rv = self.dispatch_request()
         ^^^^^^^^^^^^^^^^^^^^^^^
  File "C:\Users\andre\AppData\Local\Packages\PythonSoftwareFoundation.Python.3.11_qbz5n2kfra8p0\LocalCache\local-packages\Python311\site-packages\flask\app.py", line 902, in dispatch_request
    return self.ensure_sync(self.view_functions[rule.endpoint])(**view_args)  # type: ignore[no-any-return]
           ^^^^^^^^^^^^^^^^^^^^^^^^^^^^^^^^^^^^^^^^^^^^^^^^^^^^^^^^^^^^^^^^^
  File "C:\Users\andre\AppData\Local\Packages\PythonSoftwareFoundation.Python.3.11_qbz5n2kfra8p0\LocalCache\local-packages\Python311\site-packages\flask\app.py", line 278, in <lambda>
    view_func=lambda **kw: self_ref().send_static_file(**kw),  # type: ignore # noqa: B950
                           ^^^^^^^^^^^^^^^^^^^^^^^^^^^^^^^^^
  File "C:\Users\andre\AppData\Local\Packages\PythonSoftwareFoundation.Python.3.11_qbz5n2kfra8p0\LocalCache\local-packages\Python311\site-packages\flask\app.py", line 326, in send_static_file
    return send_from_directory(
           ^^^^^^^^^^^^^^^^^^^^
  File "C:\Users\andre\AppData\Local\Packages\PythonSoftwareFoundation.Python.3.11_qbz5n2kfra8p0\LocalCache\local-packages\Python311\site-packages\flask\helpers.py", line 565, in send_from_directory
    return werkzeug.utils.send_from_directory(  # type: ignore[return-value]
           ^^^^^^^^^^^^^^^^^^^^^^^^^^^^^^^^^^^^^^^^^^^^^^^^^^^^^^^^^^^^^^^^^
  File "C:\Users\andre\AppData\Local\Packages\PythonSoftwareFoundation.Python.3.11_qbz5n2kfra8p0\LocalCache\local-packages\Python311\site-packages\werkzeug\utils.py", line 575, in send_from_directory
    raise NotFound()
werkzeug.exceptions.NotFound: 404 Not Found: The requested URL was not found on the server. If you entered the URL manually please check your spelling and try again.
2024-11-20 21:26:23,411 - INFO - 127.0.0.1 - - [20/Nov/2024 21:26:23] "[35m[1mGET /favicon.ico HTTP/1.1[0m" 500 -
2024-11-20 21:26:26,039 - INFO - Chat request received - length: 2
2024-11-20 21:26:26,040 - ERROR - Error occurred: module 'openai' has no attribute 'error'
Traceback (most recent call last):
  File "c:\Users\andre\CascadeProjects\windsurf-project\ccwithai-chatbot\app.py", line 65, in chat
    app.logger.info("Context prepared for OpenAI...")
               ^^^^^^^^^^^^^^^^^^^^^^^^^^^^
  File "C:\Users\andre\AppData\Local\Packages\PythonSoftwareFoundation.Python.3.11_qbz5n2kfra8p0\LocalCache\local-packages\Python311\site-packages\openai\_utils\_proxy.py", line 22, in __getattr__
    return proxied  # pyright: ignore
               ^^^^^^^^^^^^^^^^^^^^^^
  File "C:\Users\andre\AppData\Local\Packages\PythonSoftwareFoundation.Python.3.11_qbz5n2kfra8p0\LocalCache\local-packages\Python311\site-packages\openai\_utils\_proxy.py", line 43, in __get_proxied__
    return []
           ^^^
  File "C:\Users\andre\AppData\Local\Packages\PythonSoftwareFoundation.Python.3.11_qbz5n2kfra8p0\LocalCache\local-packages\Python311\site-packages\openai\lib\_old_api.py", line 33, in __load__
    # return the proxy until it is eventually called so that
    ^^^^^^^^^^^^^^^^^^^^^^^^^^^^^^^^^^^^^^^^^
openai.lib._old_api.APIRemovedInV1: 

You tried to access openai.ChatCompletion, but this is no longer supported in openai>=1.0.0 - see the README at https://github.com/openai/openai-python for the API.

You can run `openai migrate` to automatically upgrade your codebase to use the 1.0.0 interface. 

Alternatively, you can pin your installation to the old version, e.g. `pip install openai==0.28`

A detailed migration guide is available here: https://github.com/openai/openai-python/discussions/742


During handling of the above exception, another exception occurred:

Traceback (most recent call last):
  File "C:\Users\andre\AppData\Local\Packages\PythonSoftwareFoundation.Python.3.11_qbz5n2kfra8p0\LocalCache\local-packages\Python311\site-packages\flask\app.py", line 917, in full_dispatch_request
    rv = self.dispatch_request()
         ^^^^^^^^^^^^^^^^^^^^^^^
  File "C:\Users\andre\AppData\Local\Packages\PythonSoftwareFoundation.Python.3.11_qbz5n2kfra8p0\LocalCache\local-packages\Python311\site-packages\flask\app.py", line 902, in dispatch_request
    return self.ensure_sync(self.view_functions[rule.endpoint])(**view_args)  # type: ignore[no-any-return]
           ^^^^^^^^^^^^^^^^^^^^^^^^^^^^^^^^^^^^^^^^^^^^^^^^^^^^^^^^^^^^^^^^^
  File "c:\Users\andre\CascadeProjects\windsurf-project\ccwithai-chatbot\app.py", line 84, in chat
    # Log successful response (without sensitive data)
    ^^^^^^^^^^^^
AttributeError: module 'openai' has no attribute 'error'
2024-11-20 21:26:26,040 - INFO - 127.0.0.1 - - [20/Nov/2024 21:26:26] "[35m[1mPOST /api/chat HTTP/1.1[0m" 500 -
2024-11-20 21:27:11,778 - INFO - 127.0.0.1 - - [20/Nov/2024 21:27:11] "[36mGET / HTTP/1.1[0m" 304 -
2024-11-20 21:27:11,821 - ERROR - Error occurred: 404 Not Found: The requested URL was not found on the server. If you entered the URL manually please check your spelling and try again.
Traceback (most recent call last):
  File "C:\Users\andre\AppData\Local\Packages\PythonSoftwareFoundation.Python.3.11_qbz5n2kfra8p0\LocalCache\local-packages\Python311\site-packages\flask\app.py", line 917, in full_dispatch_request
    rv = self.dispatch_request()
         ^^^^^^^^^^^^^^^^^^^^^^^
  File "C:\Users\andre\AppData\Local\Packages\PythonSoftwareFoundation.Python.3.11_qbz5n2kfra8p0\LocalCache\local-packages\Python311\site-packages\flask\app.py", line 902, in dispatch_request
    return self.ensure_sync(self.view_functions[rule.endpoint])(**view_args)  # type: ignore[no-any-return]
           ^^^^^^^^^^^^^^^^^^^^^^^^^^^^^^^^^^^^^^^^^^^^^^^^^^^^^^^^^^^^^^^^^
  File "C:\Users\andre\AppData\Local\Packages\PythonSoftwareFoundation.Python.3.11_qbz5n2kfra8p0\LocalCache\local-packages\Python311\site-packages\flask\app.py", line 278, in <lambda>
    view_func=lambda **kw: self_ref().send_static_file(**kw),  # type: ignore # noqa: B950
                           ^^^^^^^^^^^^^^^^^^^^^^^^^^^^^^^^^
  File "C:\Users\andre\AppData\Local\Packages\PythonSoftwareFoundation.Python.3.11_qbz5n2kfra8p0\LocalCache\local-packages\Python311\site-packages\flask\app.py", line 326, in send_static_file
    return send_from_directory(
           ^^^^^^^^^^^^^^^^^^^^
  File "C:\Users\andre\AppData\Local\Packages\PythonSoftwareFoundation.Python.3.11_qbz5n2kfra8p0\LocalCache\local-packages\Python311\site-packages\flask\helpers.py", line 565, in send_from_directory
    return werkzeug.utils.send_from_directory(  # type: ignore[return-value]
           ^^^^^^^^^^^^^^^^^^^^^^^^^^^^^^^^^^^^^^^^^^^^^^^^^^^^^^^^^^^^^^^^^
  File "C:\Users\andre\AppData\Local\Packages\PythonSoftwareFoundation.Python.3.11_qbz5n2kfra8p0\LocalCache\local-packages\Python311\site-packages\werkzeug\utils.py", line 575, in send_from_directory
    raise NotFound()
werkzeug.exceptions.NotFound: 404 Not Found: The requested URL was not found on the server. If you entered the URL manually please check your spelling and try again.
2024-11-20 21:27:11,823 - INFO - 127.0.0.1 - - [20/Nov/2024 21:27:11] "[35m[1mGET /favicon.ico HTTP/1.1[0m" 500 -
2024-11-20 21:27:16,189 - INFO - Chat request received - length: 2
2024-11-20 21:27:16,190 - ERROR - Error occurred: module 'openai' has no attribute 'error'
Traceback (most recent call last):
  File "c:\Users\andre\CascadeProjects\windsurf-project\ccwithai-chatbot\app.py", line 65, in chat
    app.logger.info("Context prepared for OpenAI...")
               ^^^^^^^^^^^^^^^^^^^^^^^^^^^^
  File "C:\Users\andre\AppData\Local\Packages\PythonSoftwareFoundation.Python.3.11_qbz5n2kfra8p0\LocalCache\local-packages\Python311\site-packages\openai\_utils\_proxy.py", line 22, in __getattr__
    return proxied  # pyright: ignore
               ^^^^^^^^^^^^^^^^^^^^^^
  File "C:\Users\andre\AppData\Local\Packages\PythonSoftwareFoundation.Python.3.11_qbz5n2kfra8p0\LocalCache\local-packages\Python311\site-packages\openai\_utils\_proxy.py", line 43, in __get_proxied__
    return []
           ^^^
  File "C:\Users\andre\AppData\Local\Packages\PythonSoftwareFoundation.Python.3.11_qbz5n2kfra8p0\LocalCache\local-packages\Python311\site-packages\openai\lib\_old_api.py", line 33, in __load__
    # return the proxy until it is eventually called so that
    ^^^^^^^^^^^^^^^^^^^^^^^^^^^^^^^^^^^^^^^^^
openai.lib._old_api.APIRemovedInV1: 

You tried to access openai.ChatCompletion, but this is no longer supported in openai>=1.0.0 - see the README at https://github.com/openai/openai-python for the API.

You can run `openai migrate` to automatically upgrade your codebase to use the 1.0.0 interface. 

Alternatively, you can pin your installation to the old version, e.g. `pip install openai==0.28`

A detailed migration guide is available here: https://github.com/openai/openai-python/discussions/742


During handling of the above exception, another exception occurred:

Traceback (most recent call last):
  File "C:\Users\andre\AppData\Local\Packages\PythonSoftwareFoundation.Python.3.11_qbz5n2kfra8p0\LocalCache\local-packages\Python311\site-packages\flask\app.py", line 917, in full_dispatch_request
    rv = self.dispatch_request()
         ^^^^^^^^^^^^^^^^^^^^^^^
  File "C:\Users\andre\AppData\Local\Packages\PythonSoftwareFoundation.Python.3.11_qbz5n2kfra8p0\LocalCache\local-packages\Python311\site-packages\flask\app.py", line 902, in dispatch_request
    return self.ensure_sync(self.view_functions[rule.endpoint])(**view_args)  # type: ignore[no-any-return]
           ^^^^^^^^^^^^^^^^^^^^^^^^^^^^^^^^^^^^^^^^^^^^^^^^^^^^^^^^^^^^^^^^^
  File "c:\Users\andre\CascadeProjects\windsurf-project\ccwithai-chatbot\app.py", line 84, in chat
    # Log successful response (without sensitive data)
    ^^^^^^^^^^^^
AttributeError: module 'openai' has no attribute 'error'
2024-11-20 21:27:16,190 - INFO - 127.0.0.1 - - [20/Nov/2024 21:27:16] "[35m[1mPOST /api/chat HTTP/1.1[0m" 500 -
2024-11-20 21:28:32,032 - INFO - 127.0.0.1 - - [20/Nov/2024 21:28:32] "[36mGET / HTTP/1.1[0m" 304 -
2024-11-20 21:28:32,068 - ERROR - Error occurred: 404 Not Found: The requested URL was not found on the server. If you entered the URL manually please check your spelling and try again.
Traceback (most recent call last):
  File "C:\Users\andre\AppData\Local\Packages\PythonSoftwareFoundation.Python.3.11_qbz5n2kfra8p0\LocalCache\local-packages\Python311\site-packages\flask\app.py", line 917, in full_dispatch_request
    rv = self.dispatch_request()
         ^^^^^^^^^^^^^^^^^^^^^^^
  File "C:\Users\andre\AppData\Local\Packages\PythonSoftwareFoundation.Python.3.11_qbz5n2kfra8p0\LocalCache\local-packages\Python311\site-packages\flask\app.py", line 902, in dispatch_request
    return self.ensure_sync(self.view_functions[rule.endpoint])(**view_args)  # type: ignore[no-any-return]
           ^^^^^^^^^^^^^^^^^^^^^^^^^^^^^^^^^^^^^^^^^^^^^^^^^^^^^^^^^^^^^^^^^
  File "C:\Users\andre\AppData\Local\Packages\PythonSoftwareFoundation.Python.3.11_qbz5n2kfra8p0\LocalCache\local-packages\Python311\site-packages\flask\app.py", line 278, in <lambda>
    view_func=lambda **kw: self_ref().send_static_file(**kw),  # type: ignore # noqa: B950
                           ^^^^^^^^^^^^^^^^^^^^^^^^^^^^^^^^^
  File "C:\Users\andre\AppData\Local\Packages\PythonSoftwareFoundation.Python.3.11_qbz5n2kfra8p0\LocalCache\local-packages\Python311\site-packages\flask\app.py", line 326, in send_static_file
    return send_from_directory(
           ^^^^^^^^^^^^^^^^^^^^
  File "C:\Users\andre\AppData\Local\Packages\PythonSoftwareFoundation.Python.3.11_qbz5n2kfra8p0\LocalCache\local-packages\Python311\site-packages\flask\helpers.py", line 565, in send_from_directory
    return werkzeug.utils.send_from_directory(  # type: ignore[return-value]
           ^^^^^^^^^^^^^^^^^^^^^^^^^^^^^^^^^^^^^^^^^^^^^^^^^^^^^^^^^^^^^^^^^
  File "C:\Users\andre\AppData\Local\Packages\PythonSoftwareFoundation.Python.3.11_qbz5n2kfra8p0\LocalCache\local-packages\Python311\site-packages\werkzeug\utils.py", line 575, in send_from_directory
    raise NotFound()
werkzeug.exceptions.NotFound: 404 Not Found: The requested URL was not found on the server. If you entered the URL manually please check your spelling and try again.
2024-11-20 21:28:32,068 - INFO - 127.0.0.1 - - [20/Nov/2024 21:28:32] "[35m[1mGET /favicon.ico HTTP/1.1[0m" 500 -
2024-11-20 21:28:35,465 - INFO - Chat request received - length: 2
2024-11-20 21:28:35,467 - ERROR - Error occurred: module 'openai' has no attribute 'error'
Traceback (most recent call last):
  File "c:\Users\andre\CascadeProjects\windsurf-project\ccwithai-chatbot\app.py", line 65, in chat
  File "C:\Users\andre\AppData\Local\Packages\PythonSoftwareFoundation.Python.3.11_qbz5n2kfra8p0\LocalCache\local-packages\Python311\site-packages\openai\_utils\_proxy.py", line 22, in __getattr__
    return proxied  # pyright: ignore
               ^^^^^^^^^^^^^^^^^^^^^^
  File "C:\Users\andre\AppData\Local\Packages\PythonSoftwareFoundation.Python.3.11_qbz5n2kfra8p0\LocalCache\local-packages\Python311\site-packages\openai\_utils\_proxy.py", line 43, in __get_proxied__
    return []
           ^^^
  File "C:\Users\andre\AppData\Local\Packages\PythonSoftwareFoundation.Python.3.11_qbz5n2kfra8p0\LocalCache\local-packages\Python311\site-packages\openai\lib\_old_api.py", line 33, in __load__
    # return the proxy until it is eventually called so that
    ^^^^^^^^^^^^^^^^^^^^^^^^^^^^^^^^^^^^^^^^^
openai.lib._old_api.APIRemovedInV1: 

You tried to access openai.ChatCompletion, but this is no longer supported in openai>=1.0.0 - see the README at https://github.com/openai/openai-python for the API.

You can run `openai migrate` to automatically upgrade your codebase to use the 1.0.0 interface. 

Alternatively, you can pin your installation to the old version, e.g. `pip install openai==0.28`

A detailed migration guide is available here: https://github.com/openai/openai-python/discussions/742


During handling of the above exception, another exception occurred:

Traceback (most recent call last):
  File "C:\Users\andre\AppData\Local\Packages\PythonSoftwareFoundation.Python.3.11_qbz5n2kfra8p0\LocalCache\local-packages\Python311\site-packages\flask\app.py", line 917, in full_dispatch_request
    rv = self.dispatch_request()
         ^^^^^^^^^^^^^^^^^^^^^^^
  File "C:\Users\andre\AppData\Local\Packages\PythonSoftwareFoundation.Python.3.11_qbz5n2kfra8p0\LocalCache\local-packages\Python311\site-packages\flask\app.py", line 902, in dispatch_request
    return self.ensure_sync(self.view_functions[rule.endpoint])(**view_args)  # type: ignore[no-any-return]
           ^^^^^^^^^^^^^^^^^^^^^^^^^^^^^^^^^^^^^^^^^^^^^^^^^^^^^^^^^^^^^^^^^
  File "c:\Users\andre\CascadeProjects\windsurf-project\ccwithai-chatbot\app.py", line 84, in chat
    try:
       ^^
AttributeError: module 'openai' has no attribute 'error'
2024-11-20 21:28:35,468 - INFO - 127.0.0.1 - - [20/Nov/2024 21:28:35] "[35m[1mPOST /api/chat HTTP/1.1[0m" 500 -
2024-11-20 21:28:49,768 - INFO - 127.0.0.1 - - [20/Nov/2024 21:28:49] "[36mGET / HTTP/1.1[0m" 304 -
2024-11-20 21:28:49,826 - ERROR - Error occurred: 404 Not Found: The requested URL was not found on the server. If you entered the URL manually please check your spelling and try again.
Traceback (most recent call last):
  File "C:\Users\andre\AppData\Local\Packages\PythonSoftwareFoundation.Python.3.11_qbz5n2kfra8p0\LocalCache\local-packages\Python311\site-packages\flask\app.py", line 917, in full_dispatch_request
    rv = self.dispatch_request()
         ^^^^^^^^^^^^^^^^^^^^^^^
  File "C:\Users\andre\AppData\Local\Packages\PythonSoftwareFoundation.Python.3.11_qbz5n2kfra8p0\LocalCache\local-packages\Python311\site-packages\flask\app.py", line 902, in dispatch_request
    return self.ensure_sync(self.view_functions[rule.endpoint])(**view_args)  # type: ignore[no-any-return]
           ^^^^^^^^^^^^^^^^^^^^^^^^^^^^^^^^^^^^^^^^^^^^^^^^^^^^^^^^^^^^^^^^^
  File "C:\Users\andre\AppData\Local\Packages\PythonSoftwareFoundation.Python.3.11_qbz5n2kfra8p0\LocalCache\local-packages\Python311\site-packages\flask\app.py", line 278, in <lambda>
    view_func=lambda **kw: self_ref().send_static_file(**kw),  # type: ignore # noqa: B950
                           ^^^^^^^^^^^^^^^^^^^^^^^^^^^^^^^^^
  File "C:\Users\andre\AppData\Local\Packages\PythonSoftwareFoundation.Python.3.11_qbz5n2kfra8p0\LocalCache\local-packages\Python311\site-packages\flask\app.py", line 326, in send_static_file
    return send_from_directory(
           ^^^^^^^^^^^^^^^^^^^^
  File "C:\Users\andre\AppData\Local\Packages\PythonSoftwareFoundation.Python.3.11_qbz5n2kfra8p0\LocalCache\local-packages\Python311\site-packages\flask\helpers.py", line 565, in send_from_directory
    return werkzeug.utils.send_from_directory(  # type: ignore[return-value]
           ^^^^^^^^^^^^^^^^^^^^^^^^^^^^^^^^^^^^^^^^^^^^^^^^^^^^^^^^^^^^^^^^^
  File "C:\Users\andre\AppData\Local\Packages\PythonSoftwareFoundation.Python.3.11_qbz5n2kfra8p0\LocalCache\local-packages\Python311\site-packages\werkzeug\utils.py", line 575, in send_from_directory
    raise NotFound()
werkzeug.exceptions.NotFound: 404 Not Found: The requested URL was not found on the server. If you entered the URL manually please check your spelling and try again.
2024-11-20 21:28:49,828 - INFO - 127.0.0.1 - - [20/Nov/2024 21:28:49] "[35m[1mGET /favicon.ico HTTP/1.1[0m" 500 -
2024-11-20 21:28:54,141 - INFO - Chat request received - length: 2
2024-11-20 21:28:54,143 - ERROR - Error occurred: module 'openai' has no attribute 'error'
Traceback (most recent call last):
  File "c:\Users\andre\CascadeProjects\windsurf-project\ccwithai-chatbot\app.py", line 65, in chat
  File "C:\Users\andre\AppData\Local\Packages\PythonSoftwareFoundation.Python.3.11_qbz5n2kfra8p0\LocalCache\local-packages\Python311\site-packages\openai\_utils\_proxy.py", line 22, in __getattr__
    return proxied  # pyright: ignore
               ^^^^^^^^^^^^^^^^^^^^^^
  File "C:\Users\andre\AppData\Local\Packages\PythonSoftwareFoundation.Python.3.11_qbz5n2kfra8p0\LocalCache\local-packages\Python311\site-packages\openai\_utils\_proxy.py", line 43, in __get_proxied__
    return []
           ^^^
  File "C:\Users\andre\AppData\Local\Packages\PythonSoftwareFoundation.Python.3.11_qbz5n2kfra8p0\LocalCache\local-packages\Python311\site-packages\openai\lib\_old_api.py", line 33, in __load__
    # return the proxy until it is eventually called so that
    ^^^^^^^^^^^^^^^^^^^^^^^^^^^^^^^^^^^^^^^^^
openai.lib._old_api.APIRemovedInV1: 

You tried to access openai.ChatCompletion, but this is no longer supported in openai>=1.0.0 - see the README at https://github.com/openai/openai-python for the API.

You can run `openai migrate` to automatically upgrade your codebase to use the 1.0.0 interface. 

Alternatively, you can pin your installation to the old version, e.g. `pip install openai==0.28`

A detailed migration guide is available here: https://github.com/openai/openai-python/discussions/742


During handling of the above exception, another exception occurred:

Traceback (most recent call last):
  File "C:\Users\andre\AppData\Local\Packages\PythonSoftwareFoundation.Python.3.11_qbz5n2kfra8p0\LocalCache\local-packages\Python311\site-packages\flask\app.py", line 917, in full_dispatch_request
    rv = self.dispatch_request()
         ^^^^^^^^^^^^^^^^^^^^^^^
  File "C:\Users\andre\AppData\Local\Packages\PythonSoftwareFoundation.Python.3.11_qbz5n2kfra8p0\LocalCache\local-packages\Python311\site-packages\flask\app.py", line 902, in dispatch_request
    return self.ensure_sync(self.view_functions[rule.endpoint])(**view_args)  # type: ignore[no-any-return]
           ^^^^^^^^^^^^^^^^^^^^^^^^^^^^^^^^^^^^^^^^^^^^^^^^^^^^^^^^^^^^^^^^^
  File "c:\Users\andre\CascadeProjects\windsurf-project\ccwithai-chatbot\app.py", line 84, in chat
    try:
       ^^
AttributeError: module 'openai' has no attribute 'error'
2024-11-20 21:28:54,144 - INFO - 127.0.0.1 - - [20/Nov/2024 21:28:54] "[35m[1mPOST /api/chat HTTP/1.1[0m" 500 -
2024-11-20 21:30:08,607 - INFO - 127.0.0.1 - - [20/Nov/2024 21:30:08] "[36mGET / HTTP/1.1[0m" 304 -
2024-11-20 21:30:08,642 - ERROR - Error occurred: 404 Not Found: The requested URL was not found on the server. If you entered the URL manually please check your spelling and try again.
Traceback (most recent call last):
  File "C:\Users\andre\AppData\Local\Packages\PythonSoftwareFoundation.Python.3.11_qbz5n2kfra8p0\LocalCache\local-packages\Python311\site-packages\flask\app.py", line 917, in full_dispatch_request
    rv = self.dispatch_request()
         ^^^^^^^^^^^^^^^^^^^^^^^
  File "C:\Users\andre\AppData\Local\Packages\PythonSoftwareFoundation.Python.3.11_qbz5n2kfra8p0\LocalCache\local-packages\Python311\site-packages\flask\app.py", line 902, in dispatch_request
    return self.ensure_sync(self.view_functions[rule.endpoint])(**view_args)  # type: ignore[no-any-return]
           ^^^^^^^^^^^^^^^^^^^^^^^^^^^^^^^^^^^^^^^^^^^^^^^^^^^^^^^^^^^^^^^^^
  File "C:\Users\andre\AppData\Local\Packages\PythonSoftwareFoundation.Python.3.11_qbz5n2kfra8p0\LocalCache\local-packages\Python311\site-packages\flask\app.py", line 278, in <lambda>
    view_func=lambda **kw: self_ref().send_static_file(**kw),  # type: ignore # noqa: B950
                           ^^^^^^^^^^^^^^^^^^^^^^^^^^^^^^^^^
  File "C:\Users\andre\AppData\Local\Packages\PythonSoftwareFoundation.Python.3.11_qbz5n2kfra8p0\LocalCache\local-packages\Python311\site-packages\flask\app.py", line 326, in send_static_file
    return send_from_directory(
           ^^^^^^^^^^^^^^^^^^^^
  File "C:\Users\andre\AppData\Local\Packages\PythonSoftwareFoundation.Python.3.11_qbz5n2kfra8p0\LocalCache\local-packages\Python311\site-packages\flask\helpers.py", line 565, in send_from_directory
    return werkzeug.utils.send_from_directory(  # type: ignore[return-value]
           ^^^^^^^^^^^^^^^^^^^^^^^^^^^^^^^^^^^^^^^^^^^^^^^^^^^^^^^^^^^^^^^^^
  File "C:\Users\andre\AppData\Local\Packages\PythonSoftwareFoundation.Python.3.11_qbz5n2kfra8p0\LocalCache\local-packages\Python311\site-packages\werkzeug\utils.py", line 575, in send_from_directory
    raise NotFound()
werkzeug.exceptions.NotFound: 404 Not Found: The requested URL was not found on the server. If you entered the URL manually please check your spelling and try again.
2024-11-20 21:30:08,642 - INFO - 127.0.0.1 - - [20/Nov/2024 21:30:08] "[35m[1mGET /favicon.ico HTTP/1.1[0m" 500 -
2024-11-20 21:30:12,032 - INFO - Chat request received - length: 4
2024-11-20 21:30:12,033 - ERROR - Error occurred: module 'openai' has no attribute 'error'
Traceback (most recent call last):
  File "c:\Users\andre\CascadeProjects\windsurf-project\ccwithai-chatbot\app.py", line 65, in chat
    body = request.json
               ^^^^^^^^^
  File "C:\Users\andre\AppData\Local\Packages\PythonSoftwareFoundation.Python.3.11_qbz5n2kfra8p0\LocalCache\local-packages\Python311\site-packages\openai\_utils\_proxy.py", line 22, in __getattr__
    return proxied  # pyright: ignore
               ^^^^^^^^^^^^^^^^^^^^^^
  File "C:\Users\andre\AppData\Local\Packages\PythonSoftwareFoundation.Python.3.11_qbz5n2kfra8p0\LocalCache\local-packages\Python311\site-packages\openai\_utils\_proxy.py", line 43, in __get_proxied__
    return []
           ^^^
  File "C:\Users\andre\AppData\Local\Packages\PythonSoftwareFoundation.Python.3.11_qbz5n2kfra8p0\LocalCache\local-packages\Python311\site-packages\openai\lib\_old_api.py", line 33, in __load__
    # return the proxy until it is eventually called so that
    ^^^^^^^^^^^^^^^^^^^^^^^^^^^^^^^^^^^^^^^^^
openai.lib._old_api.APIRemovedInV1: 

You tried to access openai.ChatCompletion, but this is no longer supported in openai>=1.0.0 - see the README at https://github.com/openai/openai-python for the API.

You can run `openai migrate` to automatically upgrade your codebase to use the 1.0.0 interface. 

Alternatively, you can pin your installation to the old version, e.g. `pip install openai==0.28`

A detailed migration guide is available here: https://github.com/openai/openai-python/discussions/742


During handling of the above exception, another exception occurred:

Traceback (most recent call last):
  File "C:\Users\andre\AppData\Local\Packages\PythonSoftwareFoundation.Python.3.11_qbz5n2kfra8p0\LocalCache\local-packages\Python311\site-packages\flask\app.py", line 917, in full_dispatch_request
    rv = self.dispatch_request()
         ^^^^^^^^^^^^^^^^^^^^^^^
  File "C:\Users\andre\AppData\Local\Packages\PythonSoftwareFoundation.Python.3.11_qbz5n2kfra8p0\LocalCache\local-packages\Python311\site-packages\flask\app.py", line 902, in dispatch_request
    return self.ensure_sync(self.view_functions[rule.endpoint])(**view_args)  # type: ignore[no-any-return]
           ^^^^^^^^^^^^^^^^^^^^^^^^^^^^^^^^^^^^^^^^^^^^^^^^^^^^^^^^^^^^^^^^^
  File "c:\Users\andre\CascadeProjects\windsurf-project\ccwithai-chatbot\app.py", line 84, in chat
AttributeError: module 'openai' has no attribute 'error'
2024-11-20 21:30:12,034 - INFO - 127.0.0.1 - - [20/Nov/2024 21:30:12] "[35m[1mPOST /api/chat HTTP/1.1[0m" 500 -
2024-11-20 21:30:29,315 - INFO - 127.0.0.1 - - [20/Nov/2024 21:30:29] "[36mGET / HTTP/1.1[0m" 304 -
2024-11-20 21:30:29,372 - ERROR - Error occurred: 404 Not Found: The requested URL was not found on the server. If you entered the URL manually please check your spelling and try again.
Traceback (most recent call last):
  File "C:\Users\andre\AppData\Local\Packages\PythonSoftwareFoundation.Python.3.11_qbz5n2kfra8p0\LocalCache\local-packages\Python311\site-packages\flask\app.py", line 917, in full_dispatch_request
    rv = self.dispatch_request()
         ^^^^^^^^^^^^^^^^^^^^^^^
  File "C:\Users\andre\AppData\Local\Packages\PythonSoftwareFoundation.Python.3.11_qbz5n2kfra8p0\LocalCache\local-packages\Python311\site-packages\flask\app.py", line 902, in dispatch_request
    return self.ensure_sync(self.view_functions[rule.endpoint])(**view_args)  # type: ignore[no-any-return]
           ^^^^^^^^^^^^^^^^^^^^^^^^^^^^^^^^^^^^^^^^^^^^^^^^^^^^^^^^^^^^^^^^^
  File "C:\Users\andre\AppData\Local\Packages\PythonSoftwareFoundation.Python.3.11_qbz5n2kfra8p0\LocalCache\local-packages\Python311\site-packages\flask\app.py", line 278, in <lambda>
    view_func=lambda **kw: self_ref().send_static_file(**kw),  # type: ignore # noqa: B950
                           ^^^^^^^^^^^^^^^^^^^^^^^^^^^^^^^^^
  File "C:\Users\andre\AppData\Local\Packages\PythonSoftwareFoundation.Python.3.11_qbz5n2kfra8p0\LocalCache\local-packages\Python311\site-packages\flask\app.py", line 326, in send_static_file
    return send_from_directory(
           ^^^^^^^^^^^^^^^^^^^^
  File "C:\Users\andre\AppData\Local\Packages\PythonSoftwareFoundation.Python.3.11_qbz5n2kfra8p0\LocalCache\local-packages\Python311\site-packages\flask\helpers.py", line 565, in send_from_directory
    return werkzeug.utils.send_from_directory(  # type: ignore[return-value]
           ^^^^^^^^^^^^^^^^^^^^^^^^^^^^^^^^^^^^^^^^^^^^^^^^^^^^^^^^^^^^^^^^^
  File "C:\Users\andre\AppData\Local\Packages\PythonSoftwareFoundation.Python.3.11_qbz5n2kfra8p0\LocalCache\local-packages\Python311\site-packages\werkzeug\utils.py", line 575, in send_from_directory
    raise NotFound()
werkzeug.exceptions.NotFound: 404 Not Found: The requested URL was not found on the server. If you entered the URL manually please check your spelling and try again.
2024-11-20 21:30:29,372 - INFO - 127.0.0.1 - - [20/Nov/2024 21:30:29] "[35m[1mGET /favicon.ico HTTP/1.1[0m" 500 -
2024-11-20 21:30:32,754 - INFO - Chat request received - length: 2
2024-11-20 21:30:32,754 - ERROR - Error occurred: module 'openai' has no attribute 'error'
Traceback (most recent call last):
  File "c:\Users\andre\CascadeProjects\windsurf-project\ccwithai-chatbot\app.py", line 65, in chat
    body = request.json
               ^^^^^^^^^
  File "C:\Users\andre\AppData\Local\Packages\PythonSoftwareFoundation.Python.3.11_qbz5n2kfra8p0\LocalCache\local-packages\Python311\site-packages\openai\_utils\_proxy.py", line 22, in __getattr__
    return proxied  # pyright: ignore
               ^^^^^^^^^^^^^^^^^^^^^^
  File "C:\Users\andre\AppData\Local\Packages\PythonSoftwareFoundation.Python.3.11_qbz5n2kfra8p0\LocalCache\local-packages\Python311\site-packages\openai\_utils\_proxy.py", line 43, in __get_proxied__
    return []
           ^^^
  File "C:\Users\andre\AppData\Local\Packages\PythonSoftwareFoundation.Python.3.11_qbz5n2kfra8p0\LocalCache\local-packages\Python311\site-packages\openai\lib\_old_api.py", line 33, in __load__
    # return the proxy until it is eventually called so that
    ^^^^^^^^^^^^^^^^^^^^^^^^^^^^^^^^^^^^^^^^^
openai.lib._old_api.APIRemovedInV1: 

You tried to access openai.ChatCompletion, but this is no longer supported in openai>=1.0.0 - see the README at https://github.com/openai/openai-python for the API.

You can run `openai migrate` to automatically upgrade your codebase to use the 1.0.0 interface. 

Alternatively, you can pin your installation to the old version, e.g. `pip install openai==0.28`

A detailed migration guide is available here: https://github.com/openai/openai-python/discussions/742


During handling of the above exception, another exception occurred:

Traceback (most recent call last):
  File "C:\Users\andre\AppData\Local\Packages\PythonSoftwareFoundation.Python.3.11_qbz5n2kfra8p0\LocalCache\local-packages\Python311\site-packages\flask\app.py", line 917, in full_dispatch_request
    rv = self.dispatch_request()
         ^^^^^^^^^^^^^^^^^^^^^^^
  File "C:\Users\andre\AppData\Local\Packages\PythonSoftwareFoundation.Python.3.11_qbz5n2kfra8p0\LocalCache\local-packages\Python311\site-packages\flask\app.py", line 902, in dispatch_request
    return self.ensure_sync(self.view_functions[rule.endpoint])(**view_args)  # type: ignore[no-any-return]
           ^^^^^^^^^^^^^^^^^^^^^^^^^^^^^^^^^^^^^^^^^^^^^^^^^^^^^^^^^^^^^^^^^
  File "c:\Users\andre\CascadeProjects\windsurf-project\ccwithai-chatbot\app.py", line 84, in chat
AttributeError: module 'openai' has no attribute 'error'
2024-11-20 21:30:32,754 - INFO - 127.0.0.1 - - [20/Nov/2024 21:30:32] "[35m[1mPOST /api/chat HTTP/1.1[0m" 500 -
2024-11-20 21:32:40,295 - INFO - 127.0.0.1 - - [20/Nov/2024 21:32:40] "[36mGET / HTTP/1.1[0m" 304 -
2024-11-20 21:32:40,354 - ERROR - Error occurred: 404 Not Found: The requested URL was not found on the server. If you entered the URL manually please check your spelling and try again.
Traceback (most recent call last):
  File "C:\Users\andre\AppData\Local\Packages\PythonSoftwareFoundation.Python.3.11_qbz5n2kfra8p0\LocalCache\local-packages\Python311\site-packages\flask\app.py", line 917, in full_dispatch_request
    assert request.args['vodka'] == '42'
         ^^^^^^^^^^^^^^^^^^^^^^^
  File "C:\Users\andre\AppData\Local\Packages\PythonSoftwareFoundation.Python.3.11_qbz5n2kfra8p0\LocalCache\local-packages\Python311\site-packages\flask\app.py", line 902, in dispatch_request
    exceptions to propagate to the test client.  Otherwise, the exception
           ^^^^^^^^^^^^^^^^^^^^^^^^^^^^^^^^^^^^^^^^^^^^^^^^^^^^^^^^^^^^^^^
  File "C:\Users\andre\AppData\Local\Packages\PythonSoftwareFoundation.Python.3.11_qbz5n2kfra8p0\LocalCache\local-packages\Python311\site-packages\flask\app.py", line 278, in <lambda>
  File "C:\Users\andre\AppData\Local\Packages\PythonSoftwareFoundation.Python.3.11_qbz5n2kfra8p0\LocalCache\local-packages\Python311\site-packages\flask\app.py", line 326, in send_static_file
    url_rule_class = Rule
               ^^^^^^^^^^
  File "C:\Users\andre\AppData\Local\Packages\PythonSoftwareFoundation.Python.3.11_qbz5n2kfra8p0\LocalCache\local-packages\Python311\site-packages\flask\helpers.py", line 565, in send_from_directory
    directory.
           ^^^
  File "C:\Users\andre\AppData\Local\Packages\PythonSoftwareFoundation.Python.3.11_qbz5n2kfra8p0\LocalCache\local-packages\Python311\site-packages\werkzeug\utils.py", line 575, in send_from_directory
    raise NotFound()
werkzeug.exceptions.NotFound: 404 Not Found: The requested URL was not found on the server. If you entered the URL manually please check your spelling and try again.
2024-11-20 21:32:40,354 - INFO - 127.0.0.1 - - [20/Nov/2024 21:32:40] "[35m[1mGET /favicon.ico HTTP/1.1[0m" 500 -
2024-11-20 21:32:43,411 - INFO - Chat request received - length: 2
2024-11-20 21:32:43,411 - ERROR - Error occurred: module 'openai' has no attribute 'error'
Traceback (most recent call last):
  File "c:\Users\andre\CascadeProjects\windsurf-project\ccwithai-chatbot\app.py", line 65, in chat
    except Exception as e:
                   ^^^^^^^^
  File "C:\Users\andre\AppData\Local\Packages\PythonSoftwareFoundation.Python.3.11_qbz5n2kfra8p0\LocalCache\local-packages\Python311\site-packages\openai\_utils\_proxy.py", line 22, in __getattr__
    return proxied  # pyright: ignore
               ^^^^^^^^^^^^^^^^^^^^^^
  File "C:\Users\andre\AppData\Local\Packages\PythonSoftwareFoundation.Python.3.11_qbz5n2kfra8p0\LocalCache\local-packages\Python311\site-packages\openai\_utils\_proxy.py", line 43, in __get_proxied__
    return []
           ^^^
  File "C:\Users\andre\AppData\Local\Packages\PythonSoftwareFoundation.Python.3.11_qbz5n2kfra8p0\LocalCache\local-packages\Python311\site-packages\openai\lib\_old_api.py", line 33, in __load__
    # return the proxy until it is eventually called so that
    ^^^^^^^^^^^^^^^^^^^^^^^^^^^^^^^^^^^^^^^^^
openai.lib._old_api.APIRemovedInV1: 

You tried to access openai.ChatCompletion, but this is no longer supported in openai>=1.0.0 - see the README at https://github.com/openai/openai-python for the API.

You can run `openai migrate` to automatically upgrade your codebase to use the 1.0.0 interface. 

Alternatively, you can pin your installation to the old version, e.g. `pip install openai==0.28`

A detailed migration guide is available here: https://github.com/openai/openai-python/discussions/742


During handling of the above exception, another exception occurred:

Traceback (most recent call last):
  File "C:\Users\andre\AppData\Local\Packages\PythonSoftwareFoundation.Python.3.11_qbz5n2kfra8p0\LocalCache\local-packages\Python311\site-packages\flask\app.py", line 917, in full_dispatch_request
    assert request.args['vodka'] == '42'
         ^^^^^^^^^^^^^^^^^^^^^^^
  File "C:\Users\andre\AppData\Local\Packages\PythonSoftwareFoundation.Python.3.11_qbz5n2kfra8p0\LocalCache\local-packages\Python311\site-packages\flask\app.py", line 902, in dispatch_request
    exceptions to propagate to the test client.  Otherwise, the exception
           ^^^^^^^^^^^^^^^^^^^^^^^^^^^^^^^^^^^^^^^^^^^^^^^^^^^^^^^^^^^^^^^
  File "c:\Users\andre\CascadeProjects\windsurf-project\ccwithai-chatbot\app.py", line 84, in chat
AttributeError: module 'openai' has no attribute 'error'
2024-11-20 21:32:43,415 - INFO - 127.0.0.1 - - [20/Nov/2024 21:32:43] "[35m[1mPOST /api/chat HTTP/1.1[0m" 500 -
2024-11-20 21:35:29,055 - INFO - 127.0.0.1 - - [20/Nov/2024 21:35:29] "[36mGET / HTTP/1.1[0m" 304 -
2024-11-20 21:35:29,115 - ERROR - Error occurred: 404 Not Found: The requested URL was not found on the server. If you entered the URL manually please check your spelling and try again.
Traceback (most recent call last):
  File "C:\Users\andre\AppData\Local\Packages\PythonSoftwareFoundation.Python.3.11_qbz5n2kfra8p0\LocalCache\local-packages\Python311\site-packages\flask\app.py", line 917, in full_dispatch_request
    assert request.args['vodka'] == '42'
         ^^^^^^^^^^^^^^^^^^^^^^^
  File "C:\Users\andre\AppData\Local\Packages\PythonSoftwareFoundation.Python.3.11_qbz5n2kfra8p0\LocalCache\local-packages\Python311\site-packages\flask\app.py", line 902, in dispatch_request
    exceptions to propagate to the test client.  Otherwise, the exception
           ^^^^^^^^^^^^^^^^^^^^^^^^^^^^^^^^^^^^^^^^^^^^^^^^^^^^^^^^^^^^^^^
  File "C:\Users\andre\AppData\Local\Packages\PythonSoftwareFoundation.Python.3.11_qbz5n2kfra8p0\LocalCache\local-packages\Python311\site-packages\flask\app.py", line 278, in <lambda>
  File "C:\Users\andre\AppData\Local\Packages\PythonSoftwareFoundation.Python.3.11_qbz5n2kfra8p0\LocalCache\local-packages\Python311\site-packages\flask\app.py", line 326, in send_static_file
    url_rule_class = Rule
               ^^^^^^^^^^
  File "C:\Users\andre\AppData\Local\Packages\PythonSoftwareFoundation.Python.3.11_qbz5n2kfra8p0\LocalCache\local-packages\Python311\site-packages\flask\helpers.py", line 565, in send_from_directory
    directory.
           ^^^
  File "C:\Users\andre\AppData\Local\Packages\PythonSoftwareFoundation.Python.3.11_qbz5n2kfra8p0\LocalCache\local-packages\Python311\site-packages\werkzeug\utils.py", line 575, in send_from_directory
    raise NotFound()
werkzeug.exceptions.NotFound: 404 Not Found: The requested URL was not found on the server. If you entered the URL manually please check your spelling and try again.
2024-11-20 21:35:29,117 - INFO - 127.0.0.1 - - [20/Nov/2024 21:35:29] "[35m[1mGET /favicon.ico HTTP/1.1[0m" 500 -
2024-11-20 21:35:33,178 - INFO - Chat request received - length: 2
2024-11-20 21:35:33,178 - ERROR - Error occurred: module 'openai' has no attribute 'error'
Traceback (most recent call last):
  File "c:\Users\andre\CascadeProjects\windsurf-project\ccwithai-chatbot\app.py", line 65, in chat
    temperature=0.7,
       ^^^^^^^^^^^^^^
  File "C:\Users\andre\AppData\Local\Packages\PythonSoftwareFoundation.Python.3.11_qbz5n2kfra8p0\LocalCache\local-packages\Python311\site-packages\openai\_utils\_proxy.py", line 22, in __getattr__
  File "C:\Users\andre\AppData\Local\Packages\PythonSoftwareFoundation.Python.3.11_qbz5n2kfra8p0\LocalCache\local-packages\Python311\site-packages\openai\_utils\_proxy.py", line 43, in __get_proxied__
  File "C:\Users\andre\AppData\Local\Packages\PythonSoftwareFoundation.Python.3.11_qbz5n2kfra8p0\LocalCache\local-packages\Python311\site-packages\openai\lib\_old_api.py", line 33, in __load__
openai.lib._old_api.APIRemovedInV1: 

You tried to access openai.ChatCompletion, but this is no longer supported in openai>=1.0.0 - see the README at https://github.com/openai/openai-python for the API.

You can run `openai migrate` to automatically upgrade your codebase to use the 1.0.0 interface. 

Alternatively, you can pin your installation to the old version, e.g. `pip install openai==0.28`

A detailed migration guide is available here: https://github.com/openai/openai-python/discussions/742


During handling of the above exception, another exception occurred:

Traceback (most recent call last):
  File "C:\Users\andre\AppData\Local\Packages\PythonSoftwareFoundation.Python.3.11_qbz5n2kfra8p0\LocalCache\local-packages\Python311\site-packages\flask\app.py", line 917, in full_dispatch_request
    assert request.args['vodka'] == '42'
         ^^^^^^^^^^^^^^^^^^^^^^^
  File "C:\Users\andre\AppData\Local\Packages\PythonSoftwareFoundation.Python.3.11_qbz5n2kfra8p0\LocalCache\local-packages\Python311\site-packages\flask\app.py", line 902, in dispatch_request
    exceptions to propagate to the test client.  Otherwise, the exception
           ^^^^^^^^^^^^^^^^^^^^^^^^^^^^^^^^^^^^^^^^^^^^^^^^^^^^^^^^^^^^^^^
  File "c:\Users\andre\CascadeProjects\windsurf-project\ccwithai-chatbot\app.py", line 84, in chat
AttributeError: module 'openai' has no attribute 'error'
2024-11-20 21:35:33,181 - INFO - 127.0.0.1 - - [20/Nov/2024 21:35:33] "[35m[1mPOST /api/chat HTTP/1.1[0m" 500 -
